<?xml version="1.0" ?>
<!-- =================================================================================== -->
<!-- |    This document was autogenerated by xacro from champ.urdf.xacro               | -->
<!-- |    EDITING THIS FILE BY HAND IS NOT RECOMMENDED                                 | -->
<!-- =================================================================================== -->
<robot name="champ">
  <material name="black">
    <color rgba="0.15 0.15 0.15 1.0"/>
  </material>
  <link name="base_link">
    <collision>
      <origin rpy="0 0 0" xyz="0 0 0"/>
      <geometry>
        <mesh filename="file:///home/Alexander.Karavaev/champ_ws/install/champ_description/share/champ_description/meshes/base_simple.stl" scale="0.001 0.001 0.001"/>
      </geometry>
    </collision>
    <visual>
      <origin rpy="0 0 0" xyz="0 0 0"/>
      <geometry>
        <mesh filename="file:///home/Alexander.Karavaev/champ_ws/install/champ_description/share/champ_description/meshes/base_simple.stl" scale="0.001 0.001 0.001"/>
      </geometry>
      <material name="black"/>
    </visual>
  </link>
  <link name="base_inertia">
    <inertial>
      <origin xyz="0 0 0"/>
      <mass value="2.0"/>
      <inertia ixx="0.016833333333333332" ixy="0.0" ixz="0.0" iyy="0.04448333333333333" iyz="0.0" izz="0.055683333333333335"/>
    </inertial>
  </link>
  <joint name="base_link_to_base_inertia" type="fixed">
    <parent link="base_link"/>
    <child link="base_inertia"/>
    <origin rpy="0 0 0" xyz="0 0 0"/>
  </joint>
  <!-- <link name="world"/>

    <joint name="fixed" type="fixed">
        <parent link="world"/>
        <child link="base_link"/>
      </joint> -->
  <gazebo reference="base_link">
    <material>Gazebo/FlatBlack</material>
  </gazebo>
  <joint name="hokuyo_joint" type="fixed">
    <origin rpy="0 0 0" xyz="0.0 0.0 0.10500000000000001"/>
    <parent link="base_link"/>
    <child link="hokuyo_frame"/>
  </joint>
  <link name="hokuyo_frame">
    <inertial>
      <mass value="0.270"/>
      <origin rpy="0 0 0" xyz="0 0 0"/>
      <inertia ixx="2.632e-4" ixy="0" ixz="0" iyy="2.632e-4" iyz="0" izz="1.62e-4"/>
    </inertial>
    <visual>
      <origin rpy="0 0 0" xyz="0 0 0"/>
      <geometry>
        <mesh filename="file:///home/Alexander.Karavaev/champ_ws/install/champ_description/share/champ_description/meshes/hokuyo_utm_30lx.dae"/>
      </geometry>
    </visual>
    <collision>
      <origin rpy="0 0 0" xyz="0 0 -0.0115"/>
      <geometry>
        <box size="0.058 0.058 0.087"/>
        <!--<mesh filename="package://hector_sensors_description/meshes/hokuyo_utm30lx/hokuyo_utm_30lx.stl"/>-->
      </geometry>
    </collision>
  </link>
  <gazebo reference="hokuyo_frame">
    <sensor name="hokuyo" type="ray">
      <always_on>true</always_on>
      <update_rate>30</update_rate>
      <pose>0 0 0 0 0 0</pose>
      <visualize>false</visualize>
      <ray>
        <scan>
          <horizontal>
            <samples>1040</samples>
            <resolution>1</resolution>
            <min_angle>2.2689280275926285</min_angle>
            <max_angle>-2.2689280275926285</max_angle>
          </horizontal>
        </scan>
        <range>
          <min>0.2</min>
          <max>30.0</max>
          <resolution>0.01</resolution>
        </range>
        <noise>
          <type>gaussian</type>
          <mean>0.0</mean>
          <stddev>0.004</stddev>
        </noise>
      </ray>
      <plugin filename="libgazebo_ros_ray_sensor.so" name="gazebo_ros_hokuyo_controller">
        <ros>
          <namespace>hokuyo_frame</namespace>
          <argument>~/out:=scan</argument>
        </ros>
        <!-- Set output to sensor_msgs/PointCloud to get same output type as gazebo_ros_block_laser -->
        <output_type>sensor_msgs/LaserScan</output_type>
        <!-- <frame_name> ommited, will default to block_laser_link -->
        <!-- min_intensity instead of hokuyoMinIntensity -->
        <min_intensity>100.0</min_intensity>
      </plugin>
    </sensor>
  </gazebo>
  <joint name="camera_joint" type="fixed">
    <origin rpy="0 0 0" xyz="0.25 0.0 -0.075"/>
    <parent link="base_link"/>
    <child link="camera_link"/>
  </joint>
  <link name="camera_link">
    <inertial>
      <mass value="0.200"/>
      <origin rpy="0 0 0" xyz="0 0 0"/>
      <inertia ixx="5.8083e-4" ixy="0" ixz="0" iyy="3.0833e-5" iyz="0" izz="5.9083e-4"/>
    </inertial>
    <visual>
      <origin rpy="0 0 0" xyz="0 0 0"/>
      <geometry>
        <mesh filename="file:///home/Alexander.Karavaev/champ_ws/install/champ_description/share/champ_description/meshes/asus_camera_simple.dae"/>
      </geometry>
    </visual>
    <!--        
       <collision>
          <origin xyz="0 0 0" rpy="0 0 0" />
          <geometry>
            <box size="0.035 0.185 0.025"/>
          </geometry>
        </collision>
        -->
    <collision>
      <origin rpy="0 0 0" xyz="0 0 0"/>
      <geometry>
        <mesh filename="file:///home/Alexander.Karavaev/champ_ws/install/champ_description/share/champ_description/meshes/asus_camera_simple.dae"/>
      </geometry>
    </collision>
  </link>
  <joint name="camera_depth_joint" type="fixed">
    <origin rpy="0 0 0" xyz="0.0 0.049 0.0"/>
    <parent link="camera_link"/>
    <child link="camera_depth_frame"/>
  </joint>
  <link name="camera_depth_frame"/>
  <joint name="camera_depth_optical_joint" type="fixed">
    <origin rpy="-1.5707963267948966 0.0 -1.5707963267948966" xyz="0 0 0"/>
    <parent link="camera_depth_frame"/>
    <child link="camera_depth_optical_frame"/>
  </joint>
  <link name="camera_depth_optical_frame"/>
  <joint name="camera_rgb_joint" type="fixed">
    <origin rpy="0 0 0" xyz="0.0 0.022 0.0"/>
    <parent link="camera_link"/>
    <child link="camera_rgb_frame"/>
  </joint>
  <link name="camera_rgb_frame"/>
  <joint name="camera_rgb_optical_joint" type="fixed">
    <origin rpy="-1.5707963267948966 0.0 -1.5707963267948966" xyz="0 0 0"/>
    <parent link="camera_rgb_frame"/>
    <child link="camera_rgb_optical_frame"/>
  </joint>
  <link name="camera_rgb_optical_frame"/>
  <!-- ASUS Xtion PRO camera for simulation -->
  <gazebo reference="camera_depth_frame">
    <sensor name="camera" type="depth">
      <update_rate>20</update_rate>
      <camera name="camera_depth_frame_camera">
        <horizontal_fov>1.0960667702524387</horizontal_fov>
        <image>
          <format>R8G8B8</format>
          <width>640</width>
          <height>480</height>
        </image>
        <clip>
          <near>0.5</near>
          <far>9</far>
        </clip>
      </camera>
      <!-- Set always_on only sensor, not on plugin -->
      <always_on>1</always_on>
      <!-- Set update_rate only sensor, not on plugin -->
      <update_rate>30</update_rate>
      <plugin filename="libgazebo_ros_camera.so" name="camera_camera_controller">
        <ros>
          <!-- <namespace>custom_ns</namespace> -->
          <argument>custom_camera/image_raw:=camera/rgb/image_raw</argument>
          <argument>custom_camera/image_depth:=camera/depth/image_raw</argument>
          <argument>custom_camera/camera_info:=custom_camera/custom_info_raw</argument>
          <argument>custom_camera/camera_info_depth:=camera/depth/camera_info</argument>
          <argument>custom_camera/points:=camera/depth/points</argument>
        </ros>
        <qos>
          <topic name="/camera/image_raw">
            <publisher>
              <reliability>reliable</reliability>
              <durability>volatile</durability>
              <history>keep_all</history>
              <deadline>123</deadline>
              <!-- milliseconds -->
              <lifespan>42</lifespan>
              <!-- milliseconds -->
              <liveliness>manual_by_topic</liveliness>
              <liveliness_lease_duration>1000</liveliness_lease_duration>
              <!-- milliseconds -->
            </publisher>
            <subscription>
              <reliability>reliable</reliability>
              <durability>volatile</durability>
              <history depth="3">keep_last</history>
            </subscription>
          </topic>
          <topic name="/camera/depth/image_raw">
            <publisher>
              <reliability>reliable</reliability>
              <durability>volatile</durability>
              <history>keep_all</history>
            </publisher>
            <subscription>
              <reliability>reliable</reliability>
              <durability>volatile</durability>
              <history depth="3">keep_last</history>
            </subscription>
          </topic>
          <topic name="/camera/depth/camera_info">
            <publisher>
              <reliability>reliable</reliability>
              <durability>volatile</durability>
              <history>keep_all</history>
              <deadline>123</deadline>
              <!-- milliseconds -->
              <lifespan>42</lifespan>
              <!-- milliseconds -->
              <liveliness>manual_by_topic</liveliness>
              <liveliness_lease_duration>1000</liveliness_lease_duration>
              <!-- milliseconds -->
            </publisher>
            <subscription>
              <reliability>reliable</reliability>
              <durability>volatile</durability>
              <history depth="3">keep_last</history>
            </subscription>
          </topic>
          <topic name="/camera/camera_info">
            <publisher>
              <reliability>reliable</reliability>
              <durability>volatile</durability>
              <history>keep_all</history>
              <deadline>123</deadline>
              <!-- milliseconds -->
              <lifespan>42</lifespan>
              <!-- milliseconds -->
              <liveliness>manual_by_topic</liveliness>
              <liveliness_lease_duration>1000</liveliness_lease_duration>
              <!-- milliseconds -->
            </publisher>
            <subscription>
              <reliability>reliable</reliability>
              <durability>volatile</durability>
              <history depth="3">keep_last</history>
            </subscription>
          </topic>
        </qos>
        <!-- Set camera name. If empty, defaults to sensor name (i.e. "sensor_name") -->
        <!-- <camera_name>custom_camera</camera_name> -->
        <!-- Set TF frame name. If empty, defaults to link name (i.e. "link_name") -->
        <frame_name>camera_depth_optical_frame</frame_name>
        <hack_baseline>0.07</hack_baseline>
        <!-- No need to repeat distortion parameters or to set autoDistortion -->
        <min_depth>0.001</min_depth>
        <max_depth>20.0</max_depth>
      </plugin>
    </sensor>
  </gazebo>
  <link name="imu_link">
    <inertial>
      <mass value="0.001"/>
      <origin rpy="0 0 0" xyz="0 0 0"/>
      <inertia ixx="1e-09" ixy="0.0" ixz="0.0" iyy="1e-09" iyz="0.0" izz="1e-09"/>
    </inertial>
  </link>
  <joint name="imu_joint" type="fixed">
    <parent link="base_link"/>
    <child link="imu_link"/>
  </joint>
  <gazebo reference="imu_link">
    <sensor name="imu_controller" type="imu">
      <always_on>true</always_on>
      <update_rate>50</update_rate>
      <plugin filename="libgazebo_ros_imu_sensor.so" name="gazebo_ros_imu_sensor">
        <ros>
          <namespace>/imu</namespace>
          <argument>~/out:=data</argument>
        </ros>
        <!-- <updateRate>50.0</updateRate>
                        <bodyName>imu_link</bodyName>
                        <topicName>imu/data</topicName>
                        <accelDrift>0.005 0.005 0.005</accelDrift>
                        <accelGaussianNoise>0.005 0.005 0.005</accelGaussianNoise>
                        <rateDrift>0.005 0.005 0.005 </rateDrift>
                        <rateGaussianNoise>0.005 0.005 0.005 </rateGaussianNoise>
                        <headingDrift>0.005</headingDrift>
                        <headingGaussianNoise>0.005</headingGaussianNoise> -->
      </plugin>
    </sensor>
  </gazebo>
  <!-- <xacro:include filename="$(find velodyne_description)/urdf/VLP-16.urdf.xacro"/>
        <xacro:VLP-16 parent="${base_name}" name="velodyne" topic="velodyne_points" hz="10" samples="1024" gpu="false" lasers="16" max_range="100">
            <origin xyz="0 0 ${base_height / 2}" rpy="0 0 0" />
        </xacro:VLP-16>

        <xacro:include filename="$(find champ_arm_description)/urdf/champ_arm.urdf.xacro" />
        <xacro:champ_arm parent="${base_name}">
            <origin xyz="0.07 0.0 ${base_height / 2}" rpy="0 0 0"/>
        </xacro:champ_arm> -->
  <link name="lf_hip_debug_link"/>
  <link name="lf_hip_link">
    <inertial>
      <mass value="0.25"/>
      <inertia ixx="0.00048541666666666666" ixy="0.0" ixz="0.0" iyy="0.0006134166666666667" iyz="0.0" izz="0.0003946666666666667"/>
    </inertial>
    <collision>
      <origin rpy="0 0 0" xyz="0 0 0"/>
      <geometry>
        <mesh filename="file:///home/Alexander.Karavaev/champ_ws/install/champ_description/share/champ_description/meshes/hip.stl" scale="0.001 0.001 0.001"/>
      </geometry>
    </collision>
    <visual>
      <origin rpy="0 0 0" xyz="0 0 0"/>
      <geometry>
        <mesh filename="file:///home/Alexander.Karavaev/champ_ws/install/champ_description/share/champ_description/meshes/hip.stl" scale="0.001 0.001 0.001"/>
      </geometry>
      <material name="black"/>
    </visual>
  </link>
  <gazebo reference="lf_hip_link">
    <material>Gazebo/FlatBlack</material>
  </gazebo>
  <link name="lf_upper_leg_link">
    <inertial>
      <origin xyz="0 0 -0.0705"/>
      <mass value="0.125"/>
      <inertia ixx="0.0003873984375" ixy="0.0" ixz="0.0" iyy="0.0004040651041666667" iyz="0.0" izz="3.541666666666667e-05"/>
    </inertial>
    <collision>
      <origin rpy="0 0 0" xyz="0 0 0"/>
      <geometry>
        <mesh filename="file:///home/Alexander.Karavaev/champ_ws/install/champ_description/share/champ_description/meshes/upper_leg_simple.stl" scale="0.001 0.001 0.001"/>
      </geometry>
    </collision>
    <visual>
      <origin rpy="0 0 0" xyz="0 0 0"/>
      <geometry>
        <mesh filename="file:///home/Alexander.Karavaev/champ_ws/install/champ_description/share/champ_description/meshes/upper_leg_simple.stl" scale="0.001 0.001 0.001"/>
      </geometry>
      <material name="black"/>
    </visual>
  </link>
  <gazebo reference="lf_upper_leg_link">
    <material>Gazebo/FlatBlack</material>
  </gazebo>
  <link name="lf_lower_leg_link">
    <inertial>
      <origin xyz="0 0 -0.06299999999999999"/>
      <mass value="0.125"/>
      <inertia ixx="0.00025854166666666663" ixy="0.0" ixz="0.0" iyy="0.00026934375" iyz="0.0" izz="2.0885416666666665e-05"/>
    </inertial>
    <collision>
      <origin rpy="0 0 0" xyz="0 0 0"/>
      <geometry>
        <mesh filename="file:///home/Alexander.Karavaev/champ_ws/install/champ_description/share/champ_description/meshes/lower_leg_simple.stl" scale="0.001 0.001 0.001"/>
      </geometry>
    </collision>
    <visual>
      <origin rpy="0 0 0" xyz="0 0 0"/>
      <geometry>
        <mesh filename="file:///home/Alexander.Karavaev/champ_ws/install/champ_description/share/champ_description/meshes/lower_leg_simple.stl" scale="0.001 0.001 0.001"/>
      </geometry>
      <material name="black"/>
    </visual>
  </link>
  <gazebo reference="lf_lower_leg_link">
    <kp>10000000000.0</kp>
    <kd>100.0</kd>
    <mu1>0.8</mu1>
    <mu2>0.8</mu2>
    <minDepth>0.05</minDepth>
    <material>Gazebo/FlatBlack</material>
  </gazebo>
  <link name="lf_foot_link"/>
  <!-- <link name="${leg}_foot_link_debug" /> -->
  <joint name="lf_debug_joint" type="fixed">
    <parent link="base_link"/>
    <child link="lf_hip_debug_link"/>
    <origin rpy="0 0 0" xyz="0.175 0.105 0"/>
  </joint>
  <joint name="lf_hip_joint" type="revolute">
    <axis xyz="1 0 0"/>
    <limit effort="25" lower="-3.141592653589793" upper="3.141592653589793" velocity="1.5"/>
    <parent link="base_link"/>
    <child link="lf_hip_link"/>
    <origin rpy="0 0 0" xyz="0.175 0.105 0"/>
  </joint>
  <joint name="lf_upper_leg_joint" type="revolute">
    <axis xyz="0 1 0"/>
    <limit effort="25" lower="-3.141592653589793" upper="3.141592653589793" velocity="1.5"/>
    <parent link="lf_hip_link"/>
    <child link="lf_upper_leg_link"/>
    <origin rpy="0 0 0" xyz="0 0.06 0"/>
  </joint>
  <joint name="lf_lower_leg_joint" type="revolute">
    <axis xyz="0 1 0"/>
    <limit effort="25" lower="-3.141592653589793" upper="3.141592653589793" velocity="1.5"/>
    <parent link="lf_upper_leg_link"/>
    <child link="lf_lower_leg_link"/>
    <origin rpy="0 0 0" xyz="0 0 -0.141"/>
  </joint>
  <joint name="lf_foot_joint" type="fixed">
    <parent link="lf_lower_leg_link"/>
    <child link="lf_foot_link"/>
    <origin rpy="0 0 0" xyz="0.00325 0 -0.141"/>
    <!-- <origin xyz="0 0 -${lower_leg_to_foot_distance}" rpy="0 0 0" /> -->
  </joint>
  <!-- <joint name="${leg}_debug_joint_foot" type="fixed">
            <parent link="${leg}_foot_link" />
            <child link="${leg}_foot_link_debug" />
            <origin xyz="0 0 0" rpy="0 0 0" />
        </joint> -->
  <ros2_control name="lf_hip" type="system">
    <hardware>
      <plugin>gazebo_ros2_control/GazeboSystem</plugin>
    </hardware>
    <joint name="lf_hip_joint">
      <command_interface name="effort"/>
      <state_interface name="position"/>
      <state_interface name="velocity"/>
    </joint>
  </ros2_control>
  <ros2_control name="lf_upper_leg" type="system">
    <hardware>
      <plugin>gazebo_ros2_control/GazeboSystem</plugin>
    </hardware>
    <joint name="lf_upper_leg_joint">
      <command_interface name="effort"/>
      <state_interface name="position"/>
      <state_interface name="velocity"/>
    </joint>
  </ros2_control>
  <ros2_control name="lf_lower_leg" type="system">
    <hardware>
      <plugin>gazebo_ros2_control/GazeboSystem</plugin>
    </hardware>
    <joint name="lf_lower_leg_joint">
      <command_interface name="effort"/>
      <state_interface name="position"/>
      <state_interface name="velocity"/>
    </joint>
  </ros2_control>
  <link name="lh_hip_debug_link"/>
  <link name="lh_hip_link">
    <inertial>
      <mass value="0.25"/>
      <inertia ixx="0.00048541666666666666" ixy="0.0" ixz="0.0" iyy="0.0006134166666666667" iyz="0.0" izz="0.0003946666666666667"/>
    </inertial>
    <collision>
      <origin rpy="0 0 0" xyz="0 0 0"/>
      <geometry>
        <mesh filename="file:///home/Alexander.Karavaev/champ_ws/install/champ_description/share/champ_description/meshes/hip.stl" scale="0.001 0.001 0.001"/>
      </geometry>
    </collision>
    <visual>
      <origin rpy="0 0 0" xyz="0 0 0"/>
      <geometry>
        <mesh filename="file:///home/Alexander.Karavaev/champ_ws/install/champ_description/share/champ_description/meshes/hip.stl" scale="0.001 0.001 0.001"/>
      </geometry>
      <material name="black"/>
    </visual>
  </link>
  <gazebo reference="lh_hip_link">
    <material>Gazebo/FlatBlack</material>
  </gazebo>
  <link name="lh_upper_leg_link">
    <inertial>
      <origin xyz="0 0 -0.0705"/>
      <mass value="0.125"/>
      <inertia ixx="0.0003873984375" ixy="0.0" ixz="0.0" iyy="0.0004040651041666667" iyz="0.0" izz="3.541666666666667e-05"/>
    </inertial>
    <collision>
      <origin rpy="0 0 0" xyz="0 0 0"/>
      <geometry>
        <mesh filename="file:///home/Alexander.Karavaev/champ_ws/install/champ_description/share/champ_description/meshes/upper_leg_simple.stl" scale="0.001 0.001 0.001"/>
      </geometry>
    </collision>
    <visual>
      <origin rpy="0 0 0" xyz="0 0 0"/>
      <geometry>
        <mesh filename="file:///home/Alexander.Karavaev/champ_ws/install/champ_description/share/champ_description/meshes/upper_leg_simple.stl" scale="0.001 0.001 0.001"/>
      </geometry>
      <material name="black"/>
    </visual>
  </link>
  <gazebo reference="lh_upper_leg_link">
    <material>Gazebo/FlatBlack</material>
  </gazebo>
  <link name="lh_lower_leg_link">
    <inertial>
      <origin xyz="0 0 -0.06299999999999999"/>
      <mass value="0.125"/>
      <inertia ixx="0.00025854166666666663" ixy="0.0" ixz="0.0" iyy="0.00026934375" iyz="0.0" izz="2.0885416666666665e-05"/>
    </inertial>
    <collision>
      <origin rpy="0 0 0" xyz="0 0 0"/>
      <geometry>
        <mesh filename="file:///home/Alexander.Karavaev/champ_ws/install/champ_description/share/champ_description/meshes/lower_leg_simple.stl" scale="0.001 0.001 0.001"/>
      </geometry>
    </collision>
    <visual>
      <origin rpy="0 0 0" xyz="0 0 0"/>
      <geometry>
        <mesh filename="file:///home/Alexander.Karavaev/champ_ws/install/champ_description/share/champ_description/meshes/lower_leg_simple.stl" scale="0.001 0.001 0.001"/>
      </geometry>
      <material name="black"/>
    </visual>
  </link>
  <gazebo reference="lh_lower_leg_link">
    <kp>10000000000.0</kp>
    <kd>100.0</kd>
    <mu1>0.8</mu1>
    <mu2>0.8</mu2>
    <minDepth>0.05</minDepth>
    <material>Gazebo/FlatBlack</material>
  </gazebo>
  <link name="lh_foot_link"/>
  <!-- <link name="${leg}_foot_link_debug" /> -->
  <joint name="lh_debug_joint" type="fixed">
    <parent link="base_link"/>
    <child link="lh_hip_debug_link"/>
    <origin rpy="0 0 0" xyz="-0.175 0.105 0"/>
  </joint>
  <joint name="lh_hip_joint" type="revolute">
    <axis xyz="1 0 0"/>
    <limit effort="25" lower="-3.141592653589793" upper="3.141592653589793" velocity="1.5"/>
    <parent link="base_link"/>
    <child link="lh_hip_link"/>
    <origin rpy="0 0 0" xyz="-0.175 0.105 0"/>
  </joint>
  <joint name="lh_upper_leg_joint" type="revolute">
    <axis xyz="0 1 0"/>
    <limit effort="25" lower="-3.141592653589793" upper="3.141592653589793" velocity="1.5"/>
    <parent link="lh_hip_link"/>
    <child link="lh_upper_leg_link"/>
    <origin rpy="0 0 0" xyz="0 0.06 0"/>
  </joint>
  <joint name="lh_lower_leg_joint" type="revolute">
    <axis xyz="0 1 0"/>
    <limit effort="25" lower="-3.141592653589793" upper="3.141592653589793" velocity="1.5"/>
    <parent link="lh_upper_leg_link"/>
    <child link="lh_lower_leg_link"/>
    <origin rpy="0 0 0" xyz="0 0 -0.141"/>
  </joint>
  <joint name="lh_foot_joint" type="fixed">
    <parent link="lh_lower_leg_link"/>
    <child link="lh_foot_link"/>
    <origin rpy="0 0 0" xyz="0.00325 0 -0.141"/>
    <!-- <origin xyz="0 0 -${lower_leg_to_foot_distance}" rpy="0 0 0" /> -->
  </joint>
  <!-- <joint name="${leg}_debug_joint_foot" type="fixed">
            <parent link="${leg}_foot_link" />
            <child link="${leg}_foot_link_debug" />
            <origin xyz="0 0 0" rpy="0 0 0" />
        </joint> -->
  <ros2_control name="lh_hip" type="system">
    <hardware>
      <plugin>gazebo_ros2_control/GazeboSystem</plugin>
    </hardware>
    <joint name="lh_hip_joint">
      <command_interface name="effort"/>
      <state_interface name="position"/>
      <state_interface name="velocity"/>
    </joint>
  </ros2_control>
  <ros2_control name="lh_upper_leg" type="system">
    <hardware>
      <plugin>gazebo_ros2_control/GazeboSystem</plugin>
    </hardware>
    <joint name="lh_upper_leg_joint">
      <command_interface name="effort"/>
      <state_interface name="position"/>
      <state_interface name="velocity"/>
    </joint>
  </ros2_control>
  <ros2_control name="lh_lower_leg" type="system">
    <hardware>
      <plugin>gazebo_ros2_control/GazeboSystem</plugin>
    </hardware>
    <joint name="lh_lower_leg_joint">
      <command_interface name="effort"/>
      <state_interface name="position"/>
      <state_interface name="velocity"/>
    </joint>
  </ros2_control>
  <link name="rf_hip_debug_link"/>
  <link name="rf_hip_link">
    <inertial>
      <mass value="0.25"/>
      <inertia ixx="0.00048541666666666666" ixy="0.0" ixz="0.0" iyy="0.0006134166666666667" iyz="0.0" izz="0.0003946666666666667"/>
    </inertial>
    <collision>
      <origin rpy="0 0 0" xyz="0 0 0"/>
      <geometry>
        <mesh filename="file:///home/Alexander.Karavaev/champ_ws/install/champ_description/share/champ_description/meshes/hip.stl" scale="0.001 0.001 0.001"/>
      </geometry>
    </collision>
    <visual>
      <origin rpy="0 0 0" xyz="0 0 0"/>
      <geometry>
        <mesh filename="file:///home/Alexander.Karavaev/champ_ws/install/champ_description/share/champ_description/meshes/hip.stl" scale="0.001 0.001 0.001"/>
      </geometry>
      <material name="black"/>
    </visual>
  </link>
  <gazebo reference="rf_hip_link">
    <material>Gazebo/FlatBlack</material>
  </gazebo>
  <link name="rf_upper_leg_link">
    <inertial>
      <origin xyz="0 0 -0.0705"/>
      <mass value="0.125"/>
      <inertia ixx="0.0003873984375" ixy="0.0" ixz="0.0" iyy="0.0004040651041666667" iyz="0.0" izz="3.541666666666667e-05"/>
    </inertial>
    <collision>
      <origin rpy="0 0 0" xyz="0 0 0"/>
      <geometry>
        <mesh filename="file:///home/Alexander.Karavaev/champ_ws/install/champ_description/share/champ_description/meshes/upper_leg_simple.stl" scale="0.001 0.001 0.001"/>
      </geometry>
    </collision>
    <visual>
      <origin rpy="0 0 0" xyz="0 0 0"/>
      <geometry>
        <mesh filename="file:///home/Alexander.Karavaev/champ_ws/install/champ_description/share/champ_description/meshes/upper_leg_simple.stl" scale="0.001 0.001 0.001"/>
      </geometry>
      <material name="black"/>
    </visual>
  </link>
  <gazebo reference="rf_upper_leg_link">
    <material>Gazebo/FlatBlack</material>
  </gazebo>
  <link name="rf_lower_leg_link">
    <inertial>
      <origin xyz="0 0 -0.06299999999999999"/>
      <mass value="0.125"/>
      <inertia ixx="0.00025854166666666663" ixy="0.0" ixz="0.0" iyy="0.00026934375" iyz="0.0" izz="2.0885416666666665e-05"/>
    </inertial>
    <collision>
      <origin rpy="0 0 0" xyz="0 0 0"/>
      <geometry>
        <mesh filename="file:///home/Alexander.Karavaev/champ_ws/install/champ_description/share/champ_description/meshes/lower_leg_simple.stl" scale="0.001 0.001 0.001"/>
      </geometry>
    </collision>
    <visual>
      <origin rpy="0 0 0" xyz="0 0 0"/>
      <geometry>
        <mesh filename="file:///home/Alexander.Karavaev/champ_ws/install/champ_description/share/champ_description/meshes/lower_leg_simple.stl" scale="0.001 0.001 0.001"/>
      </geometry>
      <material name="black"/>
    </visual>
  </link>
  <gazebo reference="rf_lower_leg_link">
    <kp>10000000000.0</kp>
    <kd>100.0</kd>
    <mu1>0.8</mu1>
    <mu2>0.8</mu2>
    <minDepth>0.05</minDepth>
    <material>Gazebo/FlatBlack</material>
  </gazebo>
  <link name="rf_foot_link"/>
  <!-- <link name="${leg}_foot_link_debug" /> -->
  <joint name="rf_debug_joint" type="fixed">
    <parent link="base_link"/>
    <child link="rf_hip_debug_link"/>
    <origin rpy="0 0 0" xyz="0.175 -0.105 0"/>
  </joint>
  <joint name="rf_hip_joint" type="revolute">
    <axis xyz="1 0 0"/>
    <limit effort="25" lower="-3.141592653589793" upper="3.141592653589793" velocity="1.5"/>
    <parent link="base_link"/>
    <child link="rf_hip_link"/>
    <origin rpy="0 0 0" xyz="0.175 -0.105 0"/>
  </joint>
  <joint name="rf_upper_leg_joint" type="revolute">
    <axis xyz="0 1 0"/>
    <limit effort="25" lower="-3.141592653589793" upper="3.141592653589793" velocity="1.5"/>
    <parent link="rf_hip_link"/>
    <child link="rf_upper_leg_link"/>
    <origin rpy="0 0 0" xyz="0 -0.06 0"/>
  </joint>
  <joint name="rf_lower_leg_joint" type="revolute">
    <axis xyz="0 1 0"/>
    <limit effort="25" lower="-3.141592653589793" upper="3.141592653589793" velocity="1.5"/>
    <parent link="rf_upper_leg_link"/>
    <child link="rf_lower_leg_link"/>
    <origin rpy="0 0 0" xyz="0 0 -0.141"/>
  </joint>
  <joint name="rf_foot_joint" type="fixed">
    <parent link="rf_lower_leg_link"/>
    <child link="rf_foot_link"/>
    <origin rpy="0 0 0" xyz="0.00325 0 -0.141"/>
    <!-- <origin xyz="0 0 -${lower_leg_to_foot_distance}" rpy="0 0 0" /> -->
  </joint>
  <!-- <joint name="${leg}_debug_joint_foot" type="fixed">
            <parent link="${leg}_foot_link" />
            <child link="${leg}_foot_link_debug" />
            <origin xyz="0 0 0" rpy="0 0 0" />
        </joint> -->
  <ros2_control name="rf_hip" type="system">
    <hardware>
      <plugin>gazebo_ros2_control/GazeboSystem</plugin>
    </hardware>
    <joint name="rf_hip_joint">
      <command_interface name="effort"/>
      <state_interface name="position"/>
      <state_interface name="velocity"/>
    </joint>
  </ros2_control>
  <ros2_control name="rf_upper_leg" type="system">
    <hardware>
      <plugin>gazebo_ros2_control/GazeboSystem</plugin>
    </hardware>
    <joint name="rf_upper_leg_joint">
      <command_interface name="effort"/>
      <state_interface name="position"/>
      <state_interface name="velocity"/>
    </joint>
  </ros2_control>
  <ros2_control name="rf_lower_leg" type="system">
    <hardware>
      <plugin>gazebo_ros2_control/GazeboSystem</plugin>
    </hardware>
    <joint name="rf_lower_leg_joint">
      <command_interface name="effort"/>
      <state_interface name="position"/>
      <state_interface name="velocity"/>
    </joint>
  </ros2_control>
  <link name="rh_hip_debug_link"/>
  <link name="rh_hip_link">
    <inertial>
      <mass value="0.25"/>
      <inertia ixx="0.00048541666666666666" ixy="0.0" ixz="0.0" iyy="0.0006134166666666667" iyz="0.0" izz="0.0003946666666666667"/>
    </inertial>
    <collision>
      <origin rpy="0 0 0" xyz="0 0 0"/>
      <geometry>
        <mesh filename="file:///home/Alexander.Karavaev/champ_ws/install/champ_description/share/champ_description/meshes/hip.stl" scale="0.001 0.001 0.001"/>
      </geometry>
    </collision>
    <visual>
      <origin rpy="0 0 0" xyz="0 0 0"/>
      <geometry>
        <mesh filename="file:///home/Alexander.Karavaev/champ_ws/install/champ_description/share/champ_description/meshes/hip.stl" scale="0.001 0.001 0.001"/>
      </geometry>
      <material name="black"/>
    </visual>
  </link>
  <gazebo reference="rh_hip_link">
    <material>Gazebo/FlatBlack</material>
  </gazebo>
  <link name="rh_upper_leg_link">
    <inertial>
      <origin xyz="0 0 -0.0705"/>
      <mass value="0.125"/>
      <inertia ixx="0.0003873984375" ixy="0.0" ixz="0.0" iyy="0.0004040651041666667" iyz="0.0" izz="3.541666666666667e-05"/>
    </inertial>
    <collision>
      <origin rpy="0 0 0" xyz="0 0 0"/>
      <geometry>
        <mesh filename="file:///home/Alexander.Karavaev/champ_ws/install/champ_description/share/champ_description/meshes/upper_leg_simple.stl" scale="0.001 0.001 0.001"/>
      </geometry>
    </collision>
    <visual>
      <origin rpy="0 0 0" xyz="0 0 0"/>
      <geometry>
        <mesh filename="file:///home/Alexander.Karavaev/champ_ws/install/champ_description/share/champ_description/meshes/upper_leg_simple.stl" scale="0.001 0.001 0.001"/>
      </geometry>
      <material name="black"/>
    </visual>
  </link>
  <gazebo reference="rh_upper_leg_link">
    <material>Gazebo/FlatBlack</material>
  </gazebo>
  <link name="rh_lower_leg_link">
    <inertial>
      <origin xyz="0 0 -0.06299999999999999"/>
      <mass value="0.125"/>
      <inertia ixx="0.00025854166666666663" ixy="0.0" ixz="0.0" iyy="0.00026934375" iyz="0.0" izz="2.0885416666666665e-05"/>
    </inertial>
    <collision>
      <origin rpy="0 0 0" xyz="0 0 0"/>
      <geometry>
        <mesh filename="file:///home/Alexander.Karavaev/champ_ws/install/champ_description/share/champ_description/meshes/lower_leg_simple.stl" scale="0.001 0.001 0.001"/>
      </geometry>
    </collision>
    <visual>
      <origin rpy="0 0 0" xyz="0 0 0"/>
      <geometry>
        <mesh filename="file:///home/Alexander.Karavaev/champ_ws/install/champ_description/share/champ_description/meshes/lower_leg_simple.stl" scale="0.001 0.001 0.001"/>
      </geometry>
      <material name="black"/>
    </visual>
  </link>
  <gazebo reference="rh_lower_leg_link">
    <kp>10000000000.0</kp>
    <kd>100.0</kd>
    <mu1>0.8</mu1>
    <mu2>0.8</mu2>
    <minDepth>0.05</minDepth>
    <material>Gazebo/FlatBlack</material>
  </gazebo>
  <link name="rh_foot_link"/>
  <!-- <link name="${leg}_foot_link_debug" /> -->
  <joint name="rh_debug_joint" type="fixed">
    <parent link="base_link"/>
    <child link="rh_hip_debug_link"/>
    <origin rpy="0 0 0" xyz="-0.175 -0.105 0"/>
  </joint>
  <joint name="rh_hip_joint" type="revolute">
    <axis xyz="1 0 0"/>
    <limit effort="25" lower="-3.141592653589793" upper="3.141592653589793" velocity="1.5"/>
    <parent link="base_link"/>
    <child link="rh_hip_link"/>
    <origin rpy="0 0 0" xyz="-0.175 -0.105 0"/>
  </joint>
  <joint name="rh_upper_leg_joint" type="revolute">
    <axis xyz="0 1 0"/>
    <limit effort="25" lower="-3.141592653589793" upper="3.141592653589793" velocity="1.5"/>
    <parent link="rh_hip_link"/>
    <child link="rh_upper_leg_link"/>
    <origin rpy="0 0 0" xyz="0 -0.06 0"/>
  </joint>
  <joint name="rh_lower_leg_joint" type="revolute">
    <axis xyz="0 1 0"/>
    <limit effort="25" lower="-3.141592653589793" upper="3.141592653589793" velocity="1.5"/>
    <parent link="rh_upper_leg_link"/>
    <child link="rh_lower_leg_link"/>
    <origin rpy="0 0 0" xyz="0 0 -0.141"/>
  </joint>
  <joint name="rh_foot_joint" type="fixed">
    <parent link="rh_lower_leg_link"/>
    <child link="rh_foot_link"/>
    <origin rpy="0 0 0" xyz="0.00325 0 -0.141"/>
    <!-- <origin xyz="0 0 -${lower_leg_to_foot_distance}" rpy="0 0 0" /> -->
  </joint>
  <!-- <joint name="${leg}_debug_joint_foot" type="fixed">
            <parent link="${leg}_foot_link" />
            <child link="${leg}_foot_link_debug" />
            <origin xyz="0 0 0" rpy="0 0 0" />
        </joint> -->
  <ros2_control name="rh_hip" type="system">
    <hardware>
      <plugin>gazebo_ros2_control/GazeboSystem</plugin>
    </hardware>
    <joint name="rh_hip_joint">
      <command_interface name="effort"/>
      <state_interface name="position"/>
      <state_interface name="velocity"/>
    </joint>
  </ros2_control>
  <ros2_control name="rh_upper_leg" type="system">
    <hardware>
      <plugin>gazebo_ros2_control/GazeboSystem</plugin>
    </hardware>
    <joint name="rh_upper_leg_joint">
      <command_interface name="effort"/>
      <state_interface name="position"/>
      <state_interface name="velocity"/>
    </joint>
  </ros2_control>
  <ros2_control name="rh_lower_leg" type="system">
    <hardware>
      <plugin>gazebo_ros2_control/GazeboSystem</plugin>
    </hardware>
    <joint name="rh_lower_leg_joint">
      <command_interface name="effort"/>
      <state_interface name="position"/>
      <state_interface name="velocity"/>
    </joint>
  </ros2_control>
  <gazebo>
    <plugin filename="libgazebo_ros_p3d.so" name="p3d_base_controller">
      <ros>
        <namespace>/demo</namespace>
        <argument>odom:=odom/ground_truth</argument>
      </ros>
      <body_name>base_link</body_name>
      <frame_name>world</frame_name>
      <update_rate>10.0</update_rate>
      <xyz_offset>0 0 0</xyz_offset>
      <rpy_offset>0 0 0</rpy_offset>
      <gaussian_noise>0.01</gaussian_noise>
    </plugin>
  </gazebo>
  <gazebo>
    <plugin filename="libgazebo_ros2_control.so" name="gazebo_ros2_control">
      <parameters>/home/Alexander.Karavaev/champ_ws/install/champ_gazebo/share/champ_gazebo/config/ros_control.yaml</parameters>
    </plugin>
  </gazebo>
  <!-- <gazebo>
        <plugin filename="ign_ros2_control-system" name="ign_ros2_control::IgnitionROS2ControlPlugin">
    
            <parameters>$(find champ_gazebo)/config/ros_control.yaml</parameters>
          </plugin>
    </gazebo> -->
</robot>
