<?xml version="1.0" ?>
<!-- =================================================================================== -->
<!-- |    This document was autogenerated by xacro from champ.urdf.xacro               | -->
<!-- |    EDITING THIS FILE BY HAND IS NOT RECOMMENDED                                 | -->
<!-- =================================================================================== -->
<robot name="champ" xmlns:xacro="http://ros.org/wiki/xacro">
  <material name="black">
    <color rgba="0.15 0.15 0.15 1.0"/>
  </material>
  <!-- <link name="champ"/> -->
  <link name="base_link">
    <inertial>
      <origin xyz="0.02 0 0"/>
      <mass value="2.0"/>
      <inertia ixx="0.0168333333333" ixy="0.0" ixz="0.0" iyy="0.0444833333333" iyz="0.0" izz="0.0556833333333"/>
    </inertial>
    <collision>
      <origin rpy="0 0 0" xyz="0 0 0"/>
      <geometry>
        <mesh filename="package://champ_description/meshes/base.stl" scale="0.001 0.001 0.001"/>
      </geometry>
    </collision>
    <visual>
      <origin rpy="0 0 0" xyz="0 0 0"/>
      <geometry>
        <mesh filename="package://champ_description/meshes/base.stl" scale="0.001 0.001 0.001"/>
      </geometry>
      <material name="black"/>
    </visual>
  </link>
  <gazebo reference="base_link">
    <material>Gazebo/FlatBlack</material>
  </gazebo>
  <!-- <xacro:include filename="$(find champ_description)/urdf/accessories.urdf.xacro" /> -->
  <link name="lf_hip_debug_link"/>
  <link name="lf_hip_link">
    <inertial>
      <mass value="0.25"/>
      <inertia ixx="0.000485416666667" ixy="0.0" ixz="0.0" iyy="0.000613416666667" iyz="0.0" izz="0.000394666666667"/>
    </inertial>
    <collision>
      <origin rpy="0 0 0" xyz="0 0 0"/>
      <geometry>
        <mesh filename="package://champ_description/meshes/hip.stl" scale="0.001 0.001 0.001"/>
      </geometry>
    </collision>
    <visual>
      <origin rpy="0 0 0" xyz="0 0 0"/>
      <geometry>
        <mesh filename="package://champ_description/meshes/hip.stl" scale="0.001 0.001 0.001"/>
      </geometry>
      <material name="black"/>
    </visual>
  </link>
  <gazebo reference="lf_hip_link">
    <material>Gazebo/FlatBlack</material>
  </gazebo>
  <link name="lf_upper_leg_link">
    <inertial>
      <origin xyz="0 0 -0.0705"/>
      <mass value="0.125"/>
      <inertia ixx="0.0003873984375" ixy="0.0" ixz="0.0" iyy="0.000404065104167" iyz="0.0" izz="3.54166666667e-05"/>
    </inertial>
    <collision>
      <origin rpy="0 0 0" xyz="0 0 0"/>
      <geometry>
        <mesh filename="package://champ_description/meshes/upper_leg.stl" scale="0.001 0.001 0.001"/>
      </geometry>
    </collision>
    <visual>
      <origin rpy="0 0 0" xyz="0 0 0"/>
      <geometry>
        <mesh filename="package://champ_description/meshes/upper_leg.stl" scale="0.001 0.001 0.001"/>
      </geometry>
      <material name="black"/>
    </visual>
  </link>
  <gazebo reference="lf_upper_leg_link">
    <material>Gazebo/FlatBlack</material>
  </gazebo>
  <link name="lf_lower_leg_link">
    <inertial>
      <origin xyz="0 0 -0.063"/>
      <mass value="0.125"/>
      <inertia ixx="0.000258541666667" ixy="0.0" ixz="0.0" iyy="0.00026934375" iyz="0.0" izz="2.08854166667e-05"/>
    </inertial>
    <collision>
      <origin rpy="0 0 0" xyz="0 0 0"/>
      <geometry>
        <mesh filename="package://champ_description/meshes/lower_leg.stl" scale="0.001 0.001 0.001"/>
      </geometry>
    </collision>
    <visual>
      <origin rpy="0 0 0" xyz="0 0 0"/>
      <geometry>
        <mesh filename="package://champ_description/meshes/lower_leg.stl" scale="0.001 0.001 0.001"/>
      </geometry>
      <material name="black"/>
    </visual>
  </link>
  <gazebo reference="lf_lower_leg_link">
    <kp>1000000.0</kp>
    <kd>1.0</kd>
    <mu1>0.8</mu1>
    <mu2>0.8</mu2>
    <maxVel>0.0</maxVel>
    <minDepth>0.001</minDepth>
    <material>Gazebo/FlatBlack</material>
  </gazebo>
  <link name="lf_foot_link"/>
  <joint name="lf_debug_joint" type="fixed">
    <parent link="base_link"/>
    <child link="lf_hip_debug_link"/>
    <origin rpy="0 0 0" xyz="0.175 0.105 0"/>
  </joint>
  <joint name="lf_hip_joint" type="revolute">
    <axis xyz="1 0 0"/>
    <limit effort="25" lower="-3.14159265359" upper="3.14159265359" velocity="1.5"/>
    <parent link="base_link"/>
    <child link="lf_hip_link"/>
    <origin rpy="0 0 0" xyz="0.175 0.105 0"/>
  </joint>
  <joint name="lf_upper_leg_joint" type="revolute">
    <axis xyz="0 1 0"/>
    <limit effort="25" lower="-3.14159265359" upper="3.14159265359" velocity="1.5"/>
    <parent link="lf_hip_link"/>
    <child link="lf_upper_leg_link"/>
    <origin rpy="0 0 0" xyz="0 0.06 0"/>
  </joint>
  <joint name="lf_lower_leg_joint" type="revolute">
    <axis xyz="0 1 0"/>
    <limit effort="25" lower="-3.14159265359" upper="3.14159265359" velocity="1.5"/>
    <parent link="lf_upper_leg_link"/>
    <child link="lf_lower_leg_link"/>
    <origin rpy="0 0 0" xyz="0 0 -0.141"/>
  </joint>
  <joint name="lf_foot_joint" type="fixed">
    <parent link="lf_lower_leg_link"/>
    <child link="lf_foot_link"/>
    <!-- <origin xyz="0.00325 0 -${lower_leg_to_foot_distance}" rpy="0 0 0" /> -->
    <origin rpy="0 0 0" xyz="0 0 -0.141"/>
  </joint>
  <transmission name="lf_hip_joint_trans">
    <type>transmission_interface/SimpleTransmission</type>
    <joint name="lf_hip_joint">
      <hardwareInterface>hardware_interface/EffortJointInterface</hardwareInterface>
    </joint>
    <actuator name="lf_hip_joint_motor">
      <hardwareInterface>hardware_interface/EffortJointInterface</hardwareInterface>
      <mechanicalReduction>1</mechanicalReduction>
    </actuator>
  </transmission>
  <transmission name="lf_upper_leg_joint_trans">
    <type>transmission_interface/SimpleTransmission</type>
    <joint name="lf_upper_leg_joint">
      <hardwareInterface>hardware_interface/EffortJointInterface</hardwareInterface>
    </joint>
    <actuator name="lf_upper_leg_joint_motor">
      <hardwareInterface>hardware_interface/EffortJointInterface</hardwareInterface>
      <mechanicalReduction>1</mechanicalReduction>
    </actuator>
  </transmission>
  <transmission name="lf_lower_leg_joint_trans">
    <type>transmission_interface/SimpleTransmission</type>
    <joint name="lf_lower_leg_joint">
      <hardwareInterface>hardware_interface/EffortJointInterface</hardwareInterface>
    </joint>
    <actuator name="lf_lower_joint_motor">
      <hardwareInterface>hardware_interface/EffortJointInterface</hardwareInterface>
      <mechanicalReduction>1</mechanicalReduction>
    </actuator>
  </transmission>
  <link name="lh_hip_debug_link"/>
  <link name="lh_hip_link">
    <inertial>
      <mass value="0.25"/>
      <inertia ixx="0.000485416666667" ixy="0.0" ixz="0.0" iyy="0.000613416666667" iyz="0.0" izz="0.000394666666667"/>
    </inertial>
    <collision>
      <origin rpy="0 0 0" xyz="0 0 0"/>
      <geometry>
        <mesh filename="package://champ_description/meshes/hip.stl" scale="0.001 0.001 0.001"/>
      </geometry>
    </collision>
    <visual>
      <origin rpy="0 0 0" xyz="0 0 0"/>
      <geometry>
        <mesh filename="package://champ_description/meshes/hip.stl" scale="0.001 0.001 0.001"/>
      </geometry>
      <material name="black"/>
    </visual>
  </link>
  <gazebo reference="lh_hip_link">
    <material>Gazebo/FlatBlack</material>
  </gazebo>
  <link name="lh_upper_leg_link">
    <inertial>
      <origin xyz="0 0 -0.0705"/>
      <mass value="0.125"/>
      <inertia ixx="0.0003873984375" ixy="0.0" ixz="0.0" iyy="0.000404065104167" iyz="0.0" izz="3.54166666667e-05"/>
    </inertial>
    <collision>
      <origin rpy="0 0 0" xyz="0 0 0"/>
      <geometry>
        <mesh filename="package://champ_description/meshes/upper_leg.stl" scale="0.001 0.001 0.001"/>
      </geometry>
    </collision>
    <visual>
      <origin rpy="0 0 0" xyz="0 0 0"/>
      <geometry>
        <mesh filename="package://champ_description/meshes/upper_leg.stl" scale="0.001 0.001 0.001"/>
      </geometry>
      <material name="black"/>
    </visual>
  </link>
  <gazebo reference="lh_upper_leg_link">
    <material>Gazebo/FlatBlack</material>
  </gazebo>
  <link name="lh_lower_leg_link">
    <inertial>
      <origin xyz="0 0 -0.063"/>
      <mass value="0.125"/>
      <inertia ixx="0.000258541666667" ixy="0.0" ixz="0.0" iyy="0.00026934375" iyz="0.0" izz="2.08854166667e-05"/>
    </inertial>
    <collision>
      <origin rpy="0 0 0" xyz="0 0 0"/>
      <geometry>
        <mesh filename="package://champ_description/meshes/lower_leg.stl" scale="0.001 0.001 0.001"/>
      </geometry>
    </collision>
    <visual>
      <origin rpy="0 0 0" xyz="0 0 0"/>
      <geometry>
        <mesh filename="package://champ_description/meshes/lower_leg.stl" scale="0.001 0.001 0.001"/>
      </geometry>
      <material name="black"/>
    </visual>
  </link>
  <gazebo reference="lh_lower_leg_link">
    <kp>1000000.0</kp>
    <kd>1.0</kd>
    <mu1>0.8</mu1>
    <mu2>0.8</mu2>
    <maxVel>0.0</maxVel>
    <minDepth>0.001</minDepth>
    <material>Gazebo/FlatBlack</material>
  </gazebo>
  <link name="lh_foot_link"/>
  <joint name="lh_debug_joint" type="fixed">
    <parent link="base_link"/>
    <child link="lh_hip_debug_link"/>
    <origin rpy="0 0 0" xyz="-0.175 0.105 0"/>
  </joint>
  <joint name="lh_hip_joint" type="revolute">
    <axis xyz="1 0 0"/>
    <limit effort="25" lower="-3.14159265359" upper="3.14159265359" velocity="1.5"/>
    <parent link="base_link"/>
    <child link="lh_hip_link"/>
    <origin rpy="0 0 0" xyz="-0.175 0.105 0"/>
  </joint>
  <joint name="lh_upper_leg_joint" type="revolute">
    <axis xyz="0 1 0"/>
    <limit effort="25" lower="-3.14159265359" upper="3.14159265359" velocity="1.5"/>
    <parent link="lh_hip_link"/>
    <child link="lh_upper_leg_link"/>
    <origin rpy="0 0 0" xyz="0 0.06 0"/>
  </joint>
  <joint name="lh_lower_leg_joint" type="revolute">
    <axis xyz="0 1 0"/>
    <limit effort="25" lower="-3.14159265359" upper="3.14159265359" velocity="1.5"/>
    <parent link="lh_upper_leg_link"/>
    <child link="lh_lower_leg_link"/>
    <origin rpy="0 0 0" xyz="0 0 -0.141"/>
  </joint>
  <joint name="lh_foot_joint" type="fixed">
    <parent link="lh_lower_leg_link"/>
    <child link="lh_foot_link"/>
    <!-- <origin xyz="0.00325 0 -${lower_leg_to_foot_distance}" rpy="0 0 0" /> -->
    <origin rpy="0 0 0" xyz="0 0 -0.141"/>
  </joint>
  <transmission name="lh_hip_joint_trans">
    <type>transmission_interface/SimpleTransmission</type>
    <joint name="lh_hip_joint">
      <hardwareInterface>hardware_interface/EffortJointInterface</hardwareInterface>
    </joint>
    <actuator name="lh_hip_joint_motor">
      <hardwareInterface>hardware_interface/EffortJointInterface</hardwareInterface>
      <mechanicalReduction>1</mechanicalReduction>
    </actuator>
  </transmission>
  <transmission name="lh_upper_leg_joint_trans">
    <type>transmission_interface/SimpleTransmission</type>
    <joint name="lh_upper_leg_joint">
      <hardwareInterface>hardware_interface/EffortJointInterface</hardwareInterface>
    </joint>
    <actuator name="lh_upper_leg_joint_motor">
      <hardwareInterface>hardware_interface/EffortJointInterface</hardwareInterface>
      <mechanicalReduction>1</mechanicalReduction>
    </actuator>
  </transmission>
  <transmission name="lh_lower_leg_joint_trans">
    <type>transmission_interface/SimpleTransmission</type>
    <joint name="lh_lower_leg_joint">
      <hardwareInterface>hardware_interface/EffortJointInterface</hardwareInterface>
    </joint>
    <actuator name="lh_lower_joint_motor">
      <hardwareInterface>hardware_interface/EffortJointInterface</hardwareInterface>
      <mechanicalReduction>1</mechanicalReduction>
    </actuator>
  </transmission>
  <link name="rf_hip_debug_link"/>
  <link name="rf_hip_link">
    <inertial>
      <mass value="0.25"/>
      <inertia ixx="0.000485416666667" ixy="0.0" ixz="0.0" iyy="0.000613416666667" iyz="0.0" izz="0.000394666666667"/>
    </inertial>
    <collision>
      <origin rpy="0 0 0" xyz="0 0 0"/>
      <geometry>
        <mesh filename="package://champ_description/meshes/hip.stl" scale="0.001 0.001 0.001"/>
      </geometry>
    </collision>
    <visual>
      <origin rpy="0 0 0" xyz="0 0 0"/>
      <geometry>
        <mesh filename="package://champ_description/meshes/hip.stl" scale="0.001 0.001 0.001"/>
      </geometry>
      <material name="black"/>
    </visual>
  </link>
  <gazebo reference="rf_hip_link">
    <material>Gazebo/FlatBlack</material>
  </gazebo>
  <link name="rf_upper_leg_link">
    <inertial>
      <origin xyz="0 0 -0.0705"/>
      <mass value="0.125"/>
      <inertia ixx="0.0003873984375" ixy="0.0" ixz="0.0" iyy="0.000404065104167" iyz="0.0" izz="3.54166666667e-05"/>
    </inertial>
    <collision>
      <origin rpy="0 0 0" xyz="0 0 0"/>
      <geometry>
        <mesh filename="package://champ_description/meshes/upper_leg.stl" scale="0.001 0.001 0.001"/>
      </geometry>
    </collision>
    <visual>
      <origin rpy="0 0 0" xyz="0 0 0"/>
      <geometry>
        <mesh filename="package://champ_description/meshes/upper_leg.stl" scale="0.001 0.001 0.001"/>
      </geometry>
      <material name="black"/>
    </visual>
  </link>
  <gazebo reference="rf_upper_leg_link">
    <material>Gazebo/FlatBlack</material>
  </gazebo>
  <link name="rf_lower_leg_link">
    <inertial>
      <origin xyz="0 0 -0.063"/>
      <mass value="0.125"/>
      <inertia ixx="0.000258541666667" ixy="0.0" ixz="0.0" iyy="0.00026934375" iyz="0.0" izz="2.08854166667e-05"/>
    </inertial>
    <collision>
      <origin rpy="0 0 0" xyz="0 0 0"/>
      <geometry>
        <mesh filename="package://champ_description/meshes/lower_leg.stl" scale="0.001 0.001 0.001"/>
      </geometry>
    </collision>
    <visual>
      <origin rpy="0 0 0" xyz="0 0 0"/>
      <geometry>
        <mesh filename="package://champ_description/meshes/lower_leg.stl" scale="0.001 0.001 0.001"/>
      </geometry>
      <material name="black"/>
    </visual>
  </link>
  <gazebo reference="rf_lower_leg_link">
    <kp>1000000.0</kp>
    <kd>1.0</kd>
    <mu1>0.8</mu1>
    <mu2>0.8</mu2>
    <maxVel>0.0</maxVel>
    <minDepth>0.001</minDepth>
    <material>Gazebo/FlatBlack</material>
  </gazebo>
  <link name="rf_foot_link"/>
  <joint name="rf_debug_joint" type="fixed">
    <parent link="base_link"/>
    <child link="rf_hip_debug_link"/>
    <origin rpy="0 0 0" xyz="0.175 -0.105 0"/>
  </joint>
  <joint name="rf_hip_joint" type="revolute">
    <axis xyz="1 0 0"/>
    <limit effort="25" lower="-3.14159265359" upper="3.14159265359" velocity="1.5"/>
    <parent link="base_link"/>
    <child link="rf_hip_link"/>
    <origin rpy="0 0 0" xyz="0.175 -0.105 0"/>
  </joint>
  <joint name="rf_upper_leg_joint" type="revolute">
    <axis xyz="0 1 0"/>
    <limit effort="25" lower="-3.14159265359" upper="3.14159265359" velocity="1.5"/>
    <parent link="rf_hip_link"/>
    <child link="rf_upper_leg_link"/>
    <origin rpy="0 0 0" xyz="0 -0.06 0"/>
  </joint>
  <joint name="rf_lower_leg_joint" type="revolute">
    <axis xyz="0 1 0"/>
    <limit effort="25" lower="-3.14159265359" upper="3.14159265359" velocity="1.5"/>
    <parent link="rf_upper_leg_link"/>
    <child link="rf_lower_leg_link"/>
    <origin rpy="0 0 0" xyz="0 0 -0.141"/>
  </joint>
  <joint name="rf_foot_joint" type="fixed">
    <parent link="rf_lower_leg_link"/>
    <child link="rf_foot_link"/>
    <!-- <origin xyz="0.00325 0 -${lower_leg_to_foot_distance}" rpy="0 0 0" /> -->
    <origin rpy="0 0 0" xyz="0 0 -0.141"/>
  </joint>
  <transmission name="rf_hip_joint_trans">
    <type>transmission_interface/SimpleTransmission</type>
    <joint name="rf_hip_joint">
      <hardwareInterface>hardware_interface/EffortJointInterface</hardwareInterface>
    </joint>
    <actuator name="rf_hip_joint_motor">
      <hardwareInterface>hardware_interface/EffortJointInterface</hardwareInterface>
      <mechanicalReduction>1</mechanicalReduction>
    </actuator>
  </transmission>
  <transmission name="rf_upper_leg_joint_trans">
    <type>transmission_interface/SimpleTransmission</type>
    <joint name="rf_upper_leg_joint">
      <hardwareInterface>hardware_interface/EffortJointInterface</hardwareInterface>
    </joint>
    <actuator name="rf_upper_leg_joint_motor">
      <hardwareInterface>hardware_interface/EffortJointInterface</hardwareInterface>
      <mechanicalReduction>1</mechanicalReduction>
    </actuator>
  </transmission>
  <transmission name="rf_lower_leg_joint_trans">
    <type>transmission_interface/SimpleTransmission</type>
    <joint name="rf_lower_leg_joint">
      <hardwareInterface>hardware_interface/EffortJointInterface</hardwareInterface>
    </joint>
    <actuator name="rf_lower_joint_motor">
      <hardwareInterface>hardware_interface/EffortJointInterface</hardwareInterface>
      <mechanicalReduction>1</mechanicalReduction>
    </actuator>
  </transmission>
  <link name="rh_hip_debug_link"/>
  <link name="rh_hip_link">
    <inertial>
      <mass value="0.25"/>
      <inertia ixx="0.000485416666667" ixy="0.0" ixz="0.0" iyy="0.000613416666667" iyz="0.0" izz="0.000394666666667"/>
    </inertial>
    <collision>
      <origin rpy="0 0 0" xyz="0 0 0"/>
      <geometry>
        <mesh filename="package://champ_description/meshes/hip.stl" scale="0.001 0.001 0.001"/>
      </geometry>
    </collision>
    <visual>
      <origin rpy="0 0 0" xyz="0 0 0"/>
      <geometry>
        <mesh filename="package://champ_description/meshes/hip.stl" scale="0.001 0.001 0.001"/>
      </geometry>
      <material name="black"/>
    </visual>
  </link>
  <gazebo reference="rh_hip_link">
    <material>Gazebo/FlatBlack</material>
  </gazebo>
  <link name="rh_upper_leg_link">
    <inertial>
      <origin xyz="0 0 -0.0705"/>
      <mass value="0.125"/>
      <inertia ixx="0.0003873984375" ixy="0.0" ixz="0.0" iyy="0.000404065104167" iyz="0.0" izz="3.54166666667e-05"/>
    </inertial>
    <collision>
      <origin rpy="0 0 0" xyz="0 0 0"/>
      <geometry>
        <mesh filename="package://champ_description/meshes/upper_leg.stl" scale="0.001 0.001 0.001"/>
      </geometry>
    </collision>
    <visual>
      <origin rpy="0 0 0" xyz="0 0 0"/>
      <geometry>
        <mesh filename="package://champ_description/meshes/upper_leg.stl" scale="0.001 0.001 0.001"/>
      </geometry>
      <material name="black"/>
    </visual>
  </link>
  <gazebo reference="rh_upper_leg_link">
    <material>Gazebo/FlatBlack</material>
  </gazebo>
  <link name="rh_lower_leg_link">
    <inertial>
      <origin xyz="0 0 -0.063"/>
      <mass value="0.125"/>
      <inertia ixx="0.000258541666667" ixy="0.0" ixz="0.0" iyy="0.00026934375" iyz="0.0" izz="2.08854166667e-05"/>
    </inertial>
    <collision>
      <origin rpy="0 0 0" xyz="0 0 0"/>
      <geometry>
        <mesh filename="package://champ_description/meshes/lower_leg.stl" scale="0.001 0.001 0.001"/>
      </geometry>
    </collision>
    <visual>
      <origin rpy="0 0 0" xyz="0 0 0"/>
      <geometry>
        <mesh filename="package://champ_description/meshes/lower_leg.stl" scale="0.001 0.001 0.001"/>
      </geometry>
      <material name="black"/>
    </visual>
  </link>
  <gazebo reference="rh_lower_leg_link">
    <kp>1000000.0</kp>
    <kd>1.0</kd>
    <mu1>0.8</mu1>
    <mu2>0.8</mu2>
    <maxVel>0.0</maxVel>
    <minDepth>0.001</minDepth>
    <material>Gazebo/FlatBlack</material>
  </gazebo>
  <link name="rh_foot_link"/>
  <joint name="rh_debug_joint" type="fixed">
    <parent link="base_link"/>
    <child link="rh_hip_debug_link"/>
    <origin rpy="0 0 0" xyz="-0.175 -0.105 0"/>
  </joint>
  <joint name="rh_hip_joint" type="revolute">
    <axis xyz="1 0 0"/>
    <limit effort="25" lower="-3.14159265359" upper="3.14159265359" velocity="1.5"/>
    <parent link="base_link"/>
    <child link="rh_hip_link"/>
    <origin rpy="0 0 0" xyz="-0.175 -0.105 0"/>
  </joint>
  <joint name="rh_upper_leg_joint" type="revolute">
    <axis xyz="0 1 0"/>
    <limit effort="25" lower="-3.14159265359" upper="3.14159265359" velocity="1.5"/>
    <parent link="rh_hip_link"/>
    <child link="rh_upper_leg_link"/>
    <origin rpy="0 0 0" xyz="0 -0.06 0"/>
  </joint>
  <joint name="rh_lower_leg_joint" type="revolute">
    <axis xyz="0 1 0"/>
    <limit effort="25" lower="-3.14159265359" upper="3.14159265359" velocity="1.5"/>
    <parent link="rh_upper_leg_link"/>
    <child link="rh_lower_leg_link"/>
    <origin rpy="0 0 0" xyz="0 0 -0.141"/>
  </joint>
  <joint name="rh_foot_joint" type="fixed">
    <parent link="rh_lower_leg_link"/>
    <child link="rh_foot_link"/>
    <!-- <origin xyz="0.00325 0 -${lower_leg_to_foot_distance}" rpy="0 0 0" /> -->
    <origin rpy="0 0 0" xyz="0 0 -0.141"/>
  </joint>
  <transmission name="rh_hip_joint_trans">
    <type>transmission_interface/SimpleTransmission</type>
    <joint name="rh_hip_joint">
      <hardwareInterface>hardware_interface/EffortJointInterface</hardwareInterface>
    </joint>
    <actuator name="rh_hip_joint_motor">
      <hardwareInterface>hardware_interface/EffortJointInterface</hardwareInterface>
      <mechanicalReduction>1</mechanicalReduction>
    </actuator>
  </transmission>
  <transmission name="rh_upper_leg_joint_trans">
    <type>transmission_interface/SimpleTransmission</type>
    <joint name="rh_upper_leg_joint">
      <hardwareInterface>hardware_interface/EffortJointInterface</hardwareInterface>
    </joint>
    <actuator name="rh_upper_leg_joint_motor">
      <hardwareInterface>hardware_interface/EffortJointInterface</hardwareInterface>
      <mechanicalReduction>1</mechanicalReduction>
    </actuator>
  </transmission>
  <transmission name="rh_lower_leg_joint_trans">
    <type>transmission_interface/SimpleTransmission</type>
    <joint name="rh_lower_leg_joint">
      <hardwareInterface>hardware_interface/EffortJointInterface</hardwareInterface>
    </joint>
    <actuator name="rh_lower_joint_motor">
      <hardwareInterface>hardware_interface/EffortJointInterface</hardwareInterface>
      <mechanicalReduction>1</mechanicalReduction>
    </actuator>
  </transmission>
  <gazebo>
    <plugin filename="libgazebo_ros_p3d.so" name="p3d_base_controller">
      <alwaysOn>true</alwaysOn>
      <updateRate>10.0</updateRate>
      <bodyName>base_link</bodyName>
      <topicName>odom/ground_truth</topicName>
      <gaussianNoise>0.01</gaussianNoise>
      <frameName>world</frameName>
      <xyzOffsets>0 0 0</xyzOffsets>
      <rpyOffsets>0 0 0</rpyOffsets>
    </plugin>
  </gazebo>
  <gazebo>
    <plugin filename="libgazebo_ros_control.so" name="gazebo_ros_control">
      <robotNamespace>/champ</robotNamespace>
      <legacyModeNS>true</legacyModeNS>
    </plugin>
  </gazebo>
</robot>

