<?xml version="1.0" encoding="utf-8"?>
<!-- =================================================================================== -->
<!-- |    This document was autogenerated by xacro from champ.urdf.xacro               | -->
<!-- |    EDITING THIS FILE BY HAND IS NOT RECOMMENDED                                 | -->
<!-- =================================================================================== -->
<robot name="champ">
  <material name="black">
    <color rgba="0.15 0.15 0.15 1.0"/>
  </material>
  <link name="base_link">
    <collision>
      <origin rpy="0 0 0" xyz="0 0 0"/>
      <geometry>
        <mesh filename="package://champ_description/meshes/base.stl" scale="0.001 0.001 0.001"/>
      </geometry>
    </collision>
    <visual>
      <origin rpy="0 0 0" xyz="0 0 0"/>
      <geometry>
        <mesh filename="package://champ_description/meshes/base.stl" scale="0.001 0.001 0.001"/>
      </geometry>
      <material name="black"/>
    </visual>
  </link>
  <link name="base_inertia">
    <inertial>
      <origin xyz="0 0 0"/>
      <mass value="2.0"/>
      <inertia ixx="0.0168333333333" ixy="0.0" ixz="0.0" iyy="0.0444833333333" iyz="0.0" izz="0.0556833333333"/>
    </inertial>
  </link>
  <joint name="base_link_to_base_inertia" type="fixed">
    <parent link="base_link"/>
    <child link="base_inertia"/>
    <origin rpy="0 0 0" xyz="0 0 0"/>
  </joint>
  <gazebo reference="base_link">
    <material>Gazebo/FlatBlack</material>
  </gazebo>
  <!-- 
    <xacro:hokuyo_utm30lx 
        name="hokuyo" 
        parent="base_link" 
        ros_topic="scan" 
        update_rate="30" 
        ray_count="1040" 
        min_angle="130" 
        max_angle="-130" >
        <origin xyz="0.0 0.0 ${base_z_length / 2 + 0.04}" rpy="0 0 0"/>
    </xacro:hokuyo_utm30lx> -->
  <gazebo reference="hokuyo_frame">
    <material>Gazebo/FlatBlack</material>
  </gazebo>
  <joint name="camera_joint" type="fixed">
    <origin rpy="0 0 0" xyz="0.25 0.0 0.075"/>
    <parent link="base_link"/>
    <child link="camera_link"/>
  </joint>
  <link name="camera_link">
    <inertial>
      <mass value="0.200"/>
      <origin rpy="0 0 0" xyz="0 0 0"/>
      <inertia ixx="5.8083e-4" ixy="0" ixz="0" iyy="3.0833e-5" iyz="0" izz="5.9083e-4"/>
    </inertial>
    <visual>
      <origin rpy="0 0 0" xyz="0 0 0"/>
      <geometry>
        <mesh filename="package://hector_sensors_description/meshes/asus_camera/asus_camera_simple.dae"/>
      </geometry>
    </visual>
    <!--        
       <collision>
          <origin xyz="0 0 0" rpy="0 0 0" />
          <geometry>
            <box size="0.035 0.185 0.025"/>
          </geometry>
        </collision>
        -->
    <collision>
      <origin rpy="0 0 0" xyz="0 0 0"/>
      <geometry>
        <mesh filename="package://hector_sensors_description/meshes/asus_camera/asus_camera_simple.dae"/>
      </geometry>
    </collision>
  </link>
  <joint name="camera_depth_joint" type="fixed">
    <origin rpy="0 0 0" xyz="0.0 0.049 0.0"/>
    <parent link="camera_link"/>
    <child link="camera_depth_frame"/>
  </joint>
  <link name="camera_depth_frame"/>
  <joint name="camera_depth_optical_joint" type="fixed">
    <origin rpy="-1.57079632679 0.0 -1.57079632679" xyz="0 0 0"/>
    <parent link="camera_depth_frame"/>
    <child link="camera_depth_optical_frame"/>
  </joint>
  <link name="camera_depth_optical_frame"/>
  <joint name="camera_rgb_joint" type="fixed">
    <origin rpy="0 0 0" xyz="0.0 0.022 0.0"/>
    <parent link="camera_link"/>
    <child link="camera_rgb_frame"/>
  </joint>
  <link name="camera_rgb_frame"/>
  <joint name="camera_rgb_optical_joint" type="fixed">
    <origin rpy="-1.57079632679 0.0 -1.57079632679" xyz="0 0 0"/>
    <parent link="camera_rgb_frame"/>
    <child link="camera_rgb_optical_frame"/>
  </joint>
  <link name="camera_rgb_optical_frame"/>
  <!-- ASUS Xtion PRO camera for simulation -->
  <gazebo reference="camera_depth_frame">
    <sensor name="camera" type="depth">
      <update_rate>20</update_rate>
      <camera>
        <horizontal_fov>1.09606677025</horizontal_fov>
        <image>
          <format>R8G8B8</format>
          <width>640</width>
          <height>480</height>
        </image>
        <clip>
          <near>0.5</near>
          <far>9</far>
        </clip>
      </camera>
      <plugin filename="libgazebo_ros_openni_kinect.so" name="camera_camera_controller">
        <imageTopicName>camera/rgb/image_raw</imageTopicName>
        <cameraInfoTopicName>camera/rgb/camera_info</cameraInfoTopicName>
        <depthImageTopicName>camera/depth/image_raw</depthImageTopicName>
        <depthImageCameraInfoTopicName>camera/depth/camera_info</depthImageCameraInfoTopicName>
        <pointCloudTopicName>camera/depth/points</pointCloudTopicName>
        <frameName>camera_depth_optical_frame</frameName>
      </plugin>
    </sensor>
  </gazebo>
  <gazebo>
    <plugin filename="libhector_gazebo_ros_imu.so" name="imu_controller">
      <updateRate>50.0</updateRate>
      <bodyName>imu_link</bodyName>
      <topicName>imu/data</topicName>
      <accelDrift>0.005 0.005 0.005</accelDrift>
      <accelGaussianNoise>0.005 0.005 0.005</accelGaussianNoise>
      <rateDrift>0.005 0.005 0.005 </rateDrift>
      <rateGaussianNoise>0.005 0.005 0.005 </rateGaussianNoise>
      <headingDrift>0.005</headingDrift>
      <headingGaussianNoise>0.005</headingGaussianNoise>
    </plugin>
  </gazebo>
  <link name="imu_link">
    <inertial>
      <mass value="0.001"/>
      <origin rpy="0 0 0" xyz="0 0 0"/>
      <inertia ixx="1e-09" ixy="0.0" ixz="0.0" iyy="1e-09" iyz="0.0" izz="1e-09"/>
    </inertial>
  </link>
  <joint name="imu_joint" type="fixed">
    <parent link="base_link"/>
    <child link="imu_link"/>
  </joint>
  <!-- <xacro:include filename="$(find champ_arm_description)/urdf/champ_arm.urdf.xacro" />
    <xacro:champ_arm parent="base_link">
        <origin xyz="0.07 0.0 ${base_z_length / 2}" rpy="0 0 0"/>
    </xacro:champ_arm> -->
   --&gt;
    
  <joint name="velodyne_base_mount_joint" type="fixed">
    <origin rpy="0 0 0" xyz="0 0 0.065"/>
    <parent link="base_link"/>
    <child link="velodyne_base_link"/>
  </joint>
  <link name="velodyne_base_link">
    <inertial>
      <mass value="0.83"/>
      <origin xyz="0 0 0.03585"/>
      <inertia ixx="0.000908059425" ixy="0" ixz="0" iyy="0.000908059425" iyz="0" izz="0.0011049624"/>
    </inertial>
    <visual>
      <geometry>
        <mesh filename="package://velodyne_description/meshes/VLP16_base_1.dae"/>
      </geometry>
    </visual>
    <visual>
      <geometry>
        <mesh filename="package://velodyne_description/meshes/VLP16_base_2.dae"/>
      </geometry>
    </visual>
    <collision>
      <origin rpy="0 0 0" xyz="0 0 0.03585"/>
      <geometry>
        <cylinder length="0.0717" radius="0.0516"/>
      </geometry>
    </collision>
  </link>
  <joint name="velodyne_base_scan_joint" type="fixed">
    <origin rpy="0 0 0" xyz="0 0 0.0377"/>
    <parent link="velodyne_base_link"/>
    <child link="velodyne"/>
  </joint>
  <link name="velodyne">
    <inertial>
      <mass value="0.01"/>
      <origin xyz="0 0 0"/>
      <inertia ixx="1e-7" ixy="0" ixz="0" iyy="1e-7" iyz="0" izz="1e-7"/>
    </inertial>
    <visual>
      <origin xyz="0 0 -0.0377"/>
      <geometry>
        <mesh filename="package://velodyne_description/meshes/VLP16_scan.dae"/>
      </geometry>
    </visual>
  </link>
  <!-- Gazebo requires the velodyne_gazebo_plugins package -->
  <gazebo reference="velodyne">
    <sensor name="velodyne-VLP16" type="ray">
      <pose>0 0 0 0 0 0</pose>
      <visualize>false</visualize>
      <update_rate>10</update_rate>
      <ray>
        <scan>
          <horizontal>
            <samples>1024</samples>
            <resolution>1</resolution>
            <min_angle>-3.14159265359</min_angle>
            <max_angle>3.14159265359</max_angle>
          </horizontal>
          <vertical>
            <samples>16</samples>
            <resolution>1</resolution>
            <min_angle>-0.261799387799</min_angle>
            <max_angle> 0.261799387799</max_angle>
          </vertical>
        </scan>
        <range>
          <min>0.3</min>
          <max>101</max>
          <resolution>0.001</resolution>
        </range>
        <noise>
          <type>gaussian</type>
          <mean>0.0</mean>
          <stddev>0.0</stddev>
        </noise>
      </ray>
      <plugin filename="libgazebo_ros_velodyne_laser.so" name="gazebo_ros_laser_controller">
        <topicName>velodyne_points</topicName>
        <frameName>velodyne</frameName>
        <min_range>0.9</min_range>
        <max_range>100</max_range>
        <gaussianNoise>0.008</gaussianNoise>
      </plugin>
    </sensor>
  </gazebo>
  <link name="lf_hip_debug_link"/>
  <link name="lf_hip_link">
    <inertial>
      <mass value="0.25"/>
      <inertia ixx="0.000485416666667" ixy="0.0" ixz="0.0" iyy="0.000613416666667" iyz="0.0" izz="0.000394666666667"/>
    </inertial>
    <collision>
      <origin rpy="0 0 0" xyz="0 0 0"/>
      <geometry>
        <mesh filename="package://champ_description/meshes/hip.stl" scale="0.001 0.001 0.001"/>
      </geometry>
    </collision>
    <visual>
      <origin rpy="0 0 0" xyz="0 0 0"/>
      <geometry>
        <mesh filename="package://champ_description/meshes/hip.stl" scale="0.001 0.001 0.001"/>
      </geometry>
      <material name="black"/>
    </visual>
  </link>
  <gazebo reference="lf_hip_link">
    <material>Gazebo/FlatBlack</material>
  </gazebo>
  <link name="lf_upper_leg_link">
    <inertial>
      <origin xyz="0 0 -0.0705"/>
      <mass value="0.125"/>
      <inertia ixx="0.0003873984375" ixy="0.0" ixz="0.0" iyy="0.000404065104167" iyz="0.0" izz="3.54166666667e-05"/>
    </inertial>
    <collision>
      <origin rpy="0 0 0" xyz="0 0 0"/>
      <geometry>
        <mesh filename="package://champ_description/meshes/upper_leg.stl" scale="0.001 0.001 0.001"/>
      </geometry>
    </collision>
    <visual>
      <origin rpy="0 0 0" xyz="0 0 0"/>
      <geometry>
        <mesh filename="package://champ_description/meshes/upper_leg.stl" scale="0.001 0.001 0.001"/>
      </geometry>
      <material name="black"/>
    </visual>
  </link>
  <gazebo reference="lf_upper_leg_link">
    <material>Gazebo/FlatBlack</material>
  </gazebo>
  <link name="lf_lower_leg_link">
    <inertial>
      <origin xyz="0 0 -0.063"/>
      <mass value="0.125"/>
      <inertia ixx="0.000258541666667" ixy="0.0" ixz="0.0" iyy="0.00026934375" iyz="0.0" izz="2.08854166667e-05"/>
    </inertial>
    <collision>
      <origin rpy="0 0 0" xyz="0 0 0"/>
      <geometry>
        <mesh filename="package://champ_description/meshes/lower_leg.stl" scale="0.001 0.001 0.001"/>
      </geometry>
    </collision>
    <visual>
      <origin rpy="0 0 0" xyz="0 0 0"/>
      <geometry>
        <mesh filename="package://champ_description/meshes/lower_leg.stl" scale="0.001 0.001 0.001"/>
      </geometry>
      <material name="black"/>
    </visual>
  </link>
  <gazebo reference="lf_lower_leg_link">
    <kp>1000000.0</kp>
    <kd>1.0</kd>
    <mu1>0.8</mu1>
    <mu2>0.8</mu2>
    <maxVel>0.0</maxVel>
    <minDepth>0.001</minDepth>
    <material>Gazebo/FlatBlack</material>
  </gazebo>
  <link name="lf_foot_link"/>
  <joint name="lf_debug_joint" type="fixed">
    <parent link="base_link"/>
    <child link="lf_hip_debug_link"/>
    <origin rpy="0 0 0" xyz="0.175 0.105 0"/>
  </joint>
  <joint name="lf_hip_joint" type="revolute">
    <axis xyz="1 0 0"/>
    <limit effort="25" lower="-3.14159265359" upper="3.14159265359" velocity="1.5"/>
    <parent link="base_link"/>
    <child link="lf_hip_link"/>
    <origin rpy="0 0 0" xyz="0.175 0.105 0"/>
  </joint>
  <joint name="lf_upper_leg_joint" type="revolute">
    <axis xyz="0 1 0"/>
    <limit effort="25" lower="-3.14159265359" upper="3.14159265359" velocity="1.5"/>
    <parent link="lf_hip_link"/>
    <child link="lf_upper_leg_link"/>
    <origin rpy="0 0 0" xyz="0 0.06 0"/>
  </joint>
  <joint name="lf_lower_leg_joint" type="revolute">
    <axis xyz="0 1 0"/>
    <limit effort="25" lower="-3.14159265359" upper="3.14159265359" velocity="1.5"/>
    <parent link="lf_upper_leg_link"/>
    <child link="lf_lower_leg_link"/>
    <origin rpy="0 0 0" xyz="0 0 -0.141"/>
  </joint>
  <joint name="lf_foot_joint" type="fixed">
    <parent link="lf_lower_leg_link"/>
    <child link="lf_foot_link"/>
    <!-- <origin xyz="0.00325 0 -${lower_leg_to_foot_distance}" rpy="0 0 0" /> -->
    <origin rpy="0 0 0" xyz="0 0 -0.141"/>
  </joint>
  <transmission name="lf_hip_joint_trans">
    <type>transmission_interface/SimpleTransmission</type>
    <joint name="lf_hip_joint">
      <hardwareInterface>hardware_interface/EffortJointInterface</hardwareInterface>
    </joint>
    <actuator name="lf_hip_joint_motor">
      <hardwareInterface>hardware_interface/EffortJointInterface</hardwareInterface>
      <mechanicalReduction>1</mechanicalReduction>
    </actuator>
  </transmission>
  <transmission name="lf_upper_leg_joint_trans">
    <type>transmission_interface/SimpleTransmission</type>
    <joint name="lf_upper_leg_joint">
      <hardwareInterface>hardware_interface/EffortJointInterface</hardwareInterface>
    </joint>
    <actuator name="lf_upper_leg_joint_motor">
      <hardwareInterface>hardware_interface/EffortJointInterface</hardwareInterface>
      <mechanicalReduction>1</mechanicalReduction>
    </actuator>
  </transmission>
  <transmission name="lf_lower_leg_joint_trans">
    <type>transmission_interface/SimpleTransmission</type>
    <joint name="lf_lower_leg_joint">
      <hardwareInterface>hardware_interface/EffortJointInterface</hardwareInterface>
    </joint>
    <actuator name="lf_lower_joint_motor">
      <hardwareInterface>hardware_interface/EffortJointInterface</hardwareInterface>
      <mechanicalReduction>1</mechanicalReduction>
    </actuator>
  </transmission>
  <link name="lh_hip_debug_link"/>
  <link name="lh_hip_link">
    <inertial>
      <mass value="0.25"/>
      <inertia ixx="0.000485416666667" ixy="0.0" ixz="0.0" iyy="0.000613416666667" iyz="0.0" izz="0.000394666666667"/>
    </inertial>
    <collision>
      <origin rpy="0 0 0" xyz="0 0 0"/>
      <geometry>
        <mesh filename="package://champ_description/meshes/hip.stl" scale="0.001 0.001 0.001"/>
      </geometry>
    </collision>
    <visual>
      <origin rpy="0 0 0" xyz="0 0 0"/>
      <geometry>
        <mesh filename="package://champ_description/meshes/hip.stl" scale="0.001 0.001 0.001"/>
      </geometry>
      <material name="black"/>
    </visual>
  </link>
  <gazebo reference="lh_hip_link">
    <material>Gazebo/FlatBlack</material>
  </gazebo>
  <link name="lh_upper_leg_link">
    <inertial>
      <origin xyz="0 0 -0.0705"/>
      <mass value="0.125"/>
      <inertia ixx="0.0003873984375" ixy="0.0" ixz="0.0" iyy="0.000404065104167" iyz="0.0" izz="3.54166666667e-05"/>
    </inertial>
    <collision>
      <origin rpy="0 0 0" xyz="0 0 0"/>
      <geometry>
        <mesh filename="package://champ_description/meshes/upper_leg.stl" scale="0.001 0.001 0.001"/>
      </geometry>
    </collision>
    <visual>
      <origin rpy="0 0 0" xyz="0 0 0"/>
      <geometry>
        <mesh filename="package://champ_description/meshes/upper_leg.stl" scale="0.001 0.001 0.001"/>
      </geometry>
      <material name="black"/>
    </visual>
  </link>
  <gazebo reference="lh_upper_leg_link">
    <material>Gazebo/FlatBlack</material>
  </gazebo>
  <link name="lh_lower_leg_link">
    <inertial>
      <origin xyz="0 0 -0.063"/>
      <mass value="0.125"/>
      <inertia ixx="0.000258541666667" ixy="0.0" ixz="0.0" iyy="0.00026934375" iyz="0.0" izz="2.08854166667e-05"/>
    </inertial>
    <collision>
      <origin rpy="0 0 0" xyz="0 0 0"/>
      <geometry>
        <mesh filename="package://champ_description/meshes/lower_leg.stl" scale="0.001 0.001 0.001"/>
      </geometry>
    </collision>
    <visual>
      <origin rpy="0 0 0" xyz="0 0 0"/>
      <geometry>
        <mesh filename="package://champ_description/meshes/lower_leg.stl" scale="0.001 0.001 0.001"/>
      </geometry>
      <material name="black"/>
    </visual>
  </link>
  <gazebo reference="lh_lower_leg_link">
    <kp>1000000.0</kp>
    <kd>1.0</kd>
    <mu1>0.8</mu1>
    <mu2>0.8</mu2>
    <maxVel>0.0</maxVel>
    <minDepth>0.001</minDepth>
    <material>Gazebo/FlatBlack</material>
  </gazebo>
  <link name="lh_foot_link"/>
  <joint name="lh_debug_joint" type="fixed">
    <parent link="base_link"/>
    <child link="lh_hip_debug_link"/>
    <origin rpy="0 0 0" xyz="-0.175 0.105 0"/>
  </joint>
  <joint name="lh_hip_joint" type="revolute">
    <axis xyz="1 0 0"/>
    <limit effort="25" lower="-3.14159265359" upper="3.14159265359" velocity="1.5"/>
    <parent link="base_link"/>
    <child link="lh_hip_link"/>
    <origin rpy="0 0 0" xyz="-0.175 0.105 0"/>
  </joint>
  <joint name="lh_upper_leg_joint" type="revolute">
    <axis xyz="0 1 0"/>
    <limit effort="25" lower="-3.14159265359" upper="3.14159265359" velocity="1.5"/>
    <parent link="lh_hip_link"/>
    <child link="lh_upper_leg_link"/>
    <origin rpy="0 0 0" xyz="0 0.06 0"/>
  </joint>
  <joint name="lh_lower_leg_joint" type="revolute">
    <axis xyz="0 1 0"/>
    <limit effort="25" lower="-3.14159265359" upper="3.14159265359" velocity="1.5"/>
    <parent link="lh_upper_leg_link"/>
    <child link="lh_lower_leg_link"/>
    <origin rpy="0 0 0" xyz="0 0 -0.141"/>
  </joint>
  <joint name="lh_foot_joint" type="fixed">
    <parent link="lh_lower_leg_link"/>
    <child link="lh_foot_link"/>
    <!-- <origin xyz="0.00325 0 -${lower_leg_to_foot_distance}" rpy="0 0 0" /> -->
    <origin rpy="0 0 0" xyz="0 0 -0.141"/>
  </joint>
  <transmission name="lh_hip_joint_trans">
    <type>transmission_interface/SimpleTransmission</type>
    <joint name="lh_hip_joint">
      <hardwareInterface>hardware_interface/EffortJointInterface</hardwareInterface>
    </joint>
    <actuator name="lh_hip_joint_motor">
      <hardwareInterface>hardware_interface/EffortJointInterface</hardwareInterface>
      <mechanicalReduction>1</mechanicalReduction>
    </actuator>
  </transmission>
  <transmission name="lh_upper_leg_joint_trans">
    <type>transmission_interface/SimpleTransmission</type>
    <joint name="lh_upper_leg_joint">
      <hardwareInterface>hardware_interface/EffortJointInterface</hardwareInterface>
    </joint>
    <actuator name="lh_upper_leg_joint_motor">
      <hardwareInterface>hardware_interface/EffortJointInterface</hardwareInterface>
      <mechanicalReduction>1</mechanicalReduction>
    </actuator>
  </transmission>
  <transmission name="lh_lower_leg_joint_trans">
    <type>transmission_interface/SimpleTransmission</type>
    <joint name="lh_lower_leg_joint">
      <hardwareInterface>hardware_interface/EffortJointInterface</hardwareInterface>
    </joint>
    <actuator name="lh_lower_joint_motor">
      <hardwareInterface>hardware_interface/EffortJointInterface</hardwareInterface>
      <mechanicalReduction>1</mechanicalReduction>
    </actuator>
  </transmission>
  <link name="rf_hip_debug_link"/>
  <link name="rf_hip_link">
    <inertial>
      <mass value="0.25"/>
      <inertia ixx="0.000485416666667" ixy="0.0" ixz="0.0" iyy="0.000613416666667" iyz="0.0" izz="0.000394666666667"/>
    </inertial>
    <collision>
      <origin rpy="0 0 0" xyz="0 0 0"/>
      <geometry>
        <mesh filename="package://champ_description/meshes/hip.stl" scale="0.001 0.001 0.001"/>
      </geometry>
    </collision>
    <visual>
      <origin rpy="0 0 0" xyz="0 0 0"/>
      <geometry>
        <mesh filename="package://champ_description/meshes/hip.stl" scale="0.001 0.001 0.001"/>
      </geometry>
      <material name="black"/>
    </visual>
  </link>
  <gazebo reference="rf_hip_link">
    <material>Gazebo/FlatBlack</material>
  </gazebo>
  <link name="rf_upper_leg_link">
    <inertial>
      <origin xyz="0 0 -0.0705"/>
      <mass value="0.125"/>
      <inertia ixx="0.0003873984375" ixy="0.0" ixz="0.0" iyy="0.000404065104167" iyz="0.0" izz="3.54166666667e-05"/>
    </inertial>
    <collision>
      <origin rpy="0 0 0" xyz="0 0 0"/>
      <geometry>
        <mesh filename="package://champ_description/meshes/upper_leg.stl" scale="0.001 0.001 0.001"/>
      </geometry>
    </collision>
    <visual>
      <origin rpy="0 0 0" xyz="0 0 0"/>
      <geometry>
        <mesh filename="package://champ_description/meshes/upper_leg.stl" scale="0.001 0.001 0.001"/>
      </geometry>
      <material name="black"/>
    </visual>
  </link>
  <gazebo reference="rf_upper_leg_link">
    <material>Gazebo/FlatBlack</material>
  </gazebo>
  <link name="rf_lower_leg_link">
    <inertial>
      <origin xyz="0 0 -0.063"/>
      <mass value="0.125"/>
      <inertia ixx="0.000258541666667" ixy="0.0" ixz="0.0" iyy="0.00026934375" iyz="0.0" izz="2.08854166667e-05"/>
    </inertial>
    <collision>
      <origin rpy="0 0 0" xyz="0 0 0"/>
      <geometry>
        <mesh filename="package://champ_description/meshes/lower_leg.stl" scale="0.001 0.001 0.001"/>
      </geometry>
    </collision>
    <visual>
      <origin rpy="0 0 0" xyz="0 0 0"/>
      <geometry>
        <mesh filename="package://champ_description/meshes/lower_leg.stl" scale="0.001 0.001 0.001"/>
      </geometry>
      <material name="black"/>
    </visual>
  </link>
  <gazebo reference="rf_lower_leg_link">
    <kp>1000000.0</kp>
    <kd>1.0</kd>
    <mu1>0.8</mu1>
    <mu2>0.8</mu2>
    <maxVel>0.0</maxVel>
    <minDepth>0.001</minDepth>
    <material>Gazebo/FlatBlack</material>
  </gazebo>
  <link name="rf_foot_link"/>
  <joint name="rf_debug_joint" type="fixed">
    <parent link="base_link"/>
    <child link="rf_hip_debug_link"/>
    <origin rpy="0 0 0" xyz="0.175 -0.105 0"/>
  </joint>
  <joint name="rf_hip_joint" type="revolute">
    <axis xyz="1 0 0"/>
    <limit effort="25" lower="-3.14159265359" upper="3.14159265359" velocity="1.5"/>
    <parent link="base_link"/>
    <child link="rf_hip_link"/>
    <origin rpy="0 0 0" xyz="0.175 -0.105 0"/>
  </joint>
  <joint name="rf_upper_leg_joint" type="revolute">
    <axis xyz="0 1 0"/>
    <limit effort="25" lower="-3.14159265359" upper="3.14159265359" velocity="1.5"/>
    <parent link="rf_hip_link"/>
    <child link="rf_upper_leg_link"/>
    <origin rpy="0 0 0" xyz="0 -0.06 0"/>
  </joint>
  <joint name="rf_lower_leg_joint" type="revolute">
    <axis xyz="0 1 0"/>
    <limit effort="25" lower="-3.14159265359" upper="3.14159265359" velocity="1.5"/>
    <parent link="rf_upper_leg_link"/>
    <child link="rf_lower_leg_link"/>
    <origin rpy="0 0 0" xyz="0 0 -0.141"/>
  </joint>
  <joint name="rf_foot_joint" type="fixed">
    <parent link="rf_lower_leg_link"/>
    <child link="rf_foot_link"/>
    <!-- <origin xyz="0.00325 0 -${lower_leg_to_foot_distance}" rpy="0 0 0" /> -->
    <origin rpy="0 0 0" xyz="0 0 -0.141"/>
  </joint>
  <transmission name="rf_hip_joint_trans">
    <type>transmission_interface/SimpleTransmission</type>
    <joint name="rf_hip_joint">
      <hardwareInterface>hardware_interface/EffortJointInterface</hardwareInterface>
    </joint>
    <actuator name="rf_hip_joint_motor">
      <hardwareInterface>hardware_interface/EffortJointInterface</hardwareInterface>
      <mechanicalReduction>1</mechanicalReduction>
    </actuator>
  </transmission>
  <transmission name="rf_upper_leg_joint_trans">
    <type>transmission_interface/SimpleTransmission</type>
    <joint name="rf_upper_leg_joint">
      <hardwareInterface>hardware_interface/EffortJointInterface</hardwareInterface>
    </joint>
    <actuator name="rf_upper_leg_joint_motor">
      <hardwareInterface>hardware_interface/EffortJointInterface</hardwareInterface>
      <mechanicalReduction>1</mechanicalReduction>
    </actuator>
  </transmission>
  <transmission name="rf_lower_leg_joint_trans">
    <type>transmission_interface/SimpleTransmission</type>
    <joint name="rf_lower_leg_joint">
      <hardwareInterface>hardware_interface/EffortJointInterface</hardwareInterface>
    </joint>
    <actuator name="rf_lower_joint_motor">
      <hardwareInterface>hardware_interface/EffortJointInterface</hardwareInterface>
      <mechanicalReduction>1</mechanicalReduction>
    </actuator>
  </transmission>
  <link name="rh_hip_debug_link"/>
  <link name="rh_hip_link">
    <inertial>
      <mass value="0.25"/>
      <inertia ixx="0.000485416666667" ixy="0.0" ixz="0.0" iyy="0.000613416666667" iyz="0.0" izz="0.000394666666667"/>
    </inertial>
    <collision>
      <origin rpy="0 0 0" xyz="0 0 0"/>
      <geometry>
        <mesh filename="package://champ_description/meshes/hip.stl" scale="0.001 0.001 0.001"/>
      </geometry>
    </collision>
    <visual>
      <origin rpy="0 0 0" xyz="0 0 0"/>
      <geometry>
        <mesh filename="package://champ_description/meshes/hip.stl" scale="0.001 0.001 0.001"/>
      </geometry>
      <material name="black"/>
    </visual>
  </link>
  <gazebo reference="rh_hip_link">
    <material>Gazebo/FlatBlack</material>
  </gazebo>
  <link name="rh_upper_leg_link">
    <inertial>
      <origin xyz="0 0 -0.0705"/>
      <mass value="0.125"/>
      <inertia ixx="0.0003873984375" ixy="0.0" ixz="0.0" iyy="0.000404065104167" iyz="0.0" izz="3.54166666667e-05"/>
    </inertial>
    <collision>
      <origin rpy="0 0 0" xyz="0 0 0"/>
      <geometry>
        <mesh filename="package://champ_description/meshes/upper_leg.stl" scale="0.001 0.001 0.001"/>
      </geometry>
    </collision>
    <visual>
      <origin rpy="0 0 0" xyz="0 0 0"/>
      <geometry>
        <mesh filename="package://champ_description/meshes/upper_leg.stl" scale="0.001 0.001 0.001"/>
      </geometry>
      <material name="black"/>
    </visual>
  </link>
  <gazebo reference="rh_upper_leg_link">
    <material>Gazebo/FlatBlack</material>
  </gazebo>
  <link name="rh_lower_leg_link">
    <inertial>
      <origin xyz="0 0 -0.063"/>
      <mass value="0.125"/>
      <inertia ixx="0.000258541666667" ixy="0.0" ixz="0.0" iyy="0.00026934375" iyz="0.0" izz="2.08854166667e-05"/>
    </inertial>
    <collision>
      <origin rpy="0 0 0" xyz="0 0 0"/>
      <geometry>
        <mesh filename="package://champ_description/meshes/lower_leg.stl" scale="0.001 0.001 0.001"/>
      </geometry>
    </collision>
    <visual>
      <origin rpy="0 0 0" xyz="0 0 0"/>
      <geometry>
        <mesh filename="package://champ_description/meshes/lower_leg.stl" scale="0.001 0.001 0.001"/>
      </geometry>
      <material name="black"/>
    </visual>
  </link>
  <gazebo reference="rh_lower_leg_link">
    <kp>1000000.0</kp>
    <kd>1.0</kd>
    <mu1>0.8</mu1>
    <mu2>0.8</mu2>
    <maxVel>0.0</maxVel>
    <minDepth>0.001</minDepth>
    <material>Gazebo/FlatBlack</material>
  </gazebo>
  <link name="rh_foot_link"/>
  <joint name="rh_debug_joint" type="fixed">
    <parent link="base_link"/>
    <child link="rh_hip_debug_link"/>
    <origin rpy="0 0 0" xyz="-0.175 -0.105 0"/>
  </joint>
  <joint name="rh_hip_joint" type="revolute">
    <axis xyz="1 0 0"/>
    <limit effort="25" lower="-3.14159265359" upper="3.14159265359" velocity="1.5"/>
    <parent link="base_link"/>
    <child link="rh_hip_link"/>
    <origin rpy="0 0 0" xyz="-0.175 -0.105 0"/>
  </joint>
  <joint name="rh_upper_leg_joint" type="revolute">
    <axis xyz="0 1 0"/>
    <limit effort="25" lower="-3.14159265359" upper="3.14159265359" velocity="1.5"/>
    <parent link="rh_hip_link"/>
    <child link="rh_upper_leg_link"/>
    <origin rpy="0 0 0" xyz="0 -0.06 0"/>
  </joint>
  <joint name="rh_lower_leg_joint" type="revolute">
    <axis xyz="0 1 0"/>
    <limit effort="25" lower="-3.14159265359" upper="3.14159265359" velocity="1.5"/>
    <parent link="rh_upper_leg_link"/>
    <child link="rh_lower_leg_link"/>
    <origin rpy="0 0 0" xyz="0 0 -0.141"/>
  </joint>
  <joint name="rh_foot_joint" type="fixed">
    <parent link="rh_lower_leg_link"/>
    <child link="rh_foot_link"/>
    <!-- <origin xyz="0.00325 0 -${lower_leg_to_foot_distance}" rpy="0 0 0" /> -->
    <origin rpy="0 0 0" xyz="0 0 -0.141"/>
  </joint>
  <transmission name="rh_hip_joint_trans">
    <type>transmission_interface/SimpleTransmission</type>
    <joint name="rh_hip_joint">
      <hardwareInterface>hardware_interface/EffortJointInterface</hardwareInterface>
    </joint>
    <actuator name="rh_hip_joint_motor">
      <hardwareInterface>hardware_interface/EffortJointInterface</hardwareInterface>
      <mechanicalReduction>1</mechanicalReduction>
    </actuator>
  </transmission>
  <transmission name="rh_upper_leg_joint_trans">
    <type>transmission_interface/SimpleTransmission</type>
    <joint name="rh_upper_leg_joint">
      <hardwareInterface>hardware_interface/EffortJointInterface</hardwareInterface>
    </joint>
    <actuator name="rh_upper_leg_joint_motor">
      <hardwareInterface>hardware_interface/EffortJointInterface</hardwareInterface>
      <mechanicalReduction>1</mechanicalReduction>
    </actuator>
  </transmission>
  <transmission name="rh_lower_leg_joint_trans">
    <type>transmission_interface/SimpleTransmission</type>
    <joint name="rh_lower_leg_joint">
      <hardwareInterface>hardware_interface/EffortJointInterface</hardwareInterface>
    </joint>
    <actuator name="rh_lower_joint_motor">
      <hardwareInterface>hardware_interface/EffortJointInterface</hardwareInterface>
      <mechanicalReduction>1</mechanicalReduction>
    </actuator>
  </transmission>
  <gazebo>
    <plugin filename="libgazebo_ros_p3d.so" name="p3d_base_controller">
      <alwaysOn>true</alwaysOn>
      <updateRate>10.0</updateRate>
      <bodyName>base_link</bodyName>
      <topicName>odom/ground_truth</topicName>
      <gaussianNoise>0.01</gaussianNoise>
      <frameName>world</frameName>
      <xyzOffsets>0 0 0</xyzOffsets>
      <rpyOffsets>0 0 0</rpyOffsets>
    </plugin>
  </gazebo>
  <gazebo>
    <plugin filename="libgazebo_ros_control.so" name="gazebo_ros_control">
      <legacyModeNS>true</legacyModeNS>
    </plugin>
  </gazebo>
</robot>

